<?xml version="1.0" ?>
<!-- =================================================================================== -->
<!-- |    This document was autogenerated by xacro from humanoid_final_copy.xacro      | -->
<!-- |    EDITING THIS FILE BY HAND IS NOT RECOMMENDED                                 | -->
<!-- =================================================================================== -->
<robot name="humanoid_final_copy">
  <material name="silver">
    <color rgba="0.700 0.700 0.700 1.000"/>
  </material>
  <transmission name="left_shoulder_flexor_tran">
    <type>transmission_interface/SimpleTransmission</type>
    <joint name="left_shoulder_flexor">
      <hardwareInterface>hardware_interface/EffortJointInterface</hardwareInterface>
    </joint>
    <actuator name="left_shoulder_flexor_actr">
      <hardwareInterface>hardware_interface/EffortJointInterface</hardwareInterface>
      <mechanicalReduction>1</mechanicalReduction>
    </actuator>
  </transmission>
  <transmission name="left_shoulder_abductor_tran">
    <type>transmission_interface/SimpleTransmission</type>
    <joint name="left_shoulder_abductor">
      <hardwareInterface>hardware_interface/EffortJointInterface</hardwareInterface>
    </joint>
    <actuator name="left_shoulder_abductor_actr">
      <hardwareInterface>hardware_interface/EffortJointInterface</hardwareInterface>
      <mechanicalReduction>1</mechanicalReduction>
    </actuator>
  </transmission>
  <transmission name="left_arm_rotor0_tran">
    <type>transmission_interface/SimpleTransmission</type>
    <joint name="left_arm_rotor0">
      <hardwareInterface>hardware_interface/EffortJointInterface</hardwareInterface>
    </joint>
    <actuator name="left_arm_rotor0_actr">
      <hardwareInterface>hardware_interface/EffortJointInterface</hardwareInterface>
      <mechanicalReduction>1</mechanicalReduction>
    </actuator>
  </transmission>
  <transmission name="left_elbow_flexor_tran">
    <type>transmission_interface/SimpleTransmission</type>
    <joint name="left_elbow_flexor">
      <hardwareInterface>hardware_interface/EffortJointInterface</hardwareInterface>
    </joint>
    <actuator name="left_elbow_flexor_actr">
      <hardwareInterface>hardware_interface/EffortJointInterface</hardwareInterface>
      <mechanicalReduction>1</mechanicalReduction>
    </actuator>
  </transmission>
  <transmission name="left_arm_rotor1_tran">
    <type>transmission_interface/SimpleTransmission</type>
    <joint name="left_arm_rotor1">
      <hardwareInterface>hardware_interface/EffortJointInterface</hardwareInterface>
    </joint>
    <actuator name="left_arm_rotor1_actr">
      <hardwareInterface>hardware_interface/EffortJointInterface</hardwareInterface>
      <mechanicalReduction>1</mechanicalReduction>
    </actuator>
  </transmission>
  <transmission name="left_wrist_abductor_tran">
    <type>transmission_interface/SimpleTransmission</type>
    <joint name="left_wrist_abductor">
      <hardwareInterface>hardware_interface/EffortJointInterface</hardwareInterface>
    </joint>
    <actuator name="left_wrist_abductor_actr">
      <hardwareInterface>hardware_interface/EffortJointInterface</hardwareInterface>
      <mechanicalReduction>1</mechanicalReduction>
    </actuator>
  </transmission>
  <transmission name="left_wrist_flexor_tran">
    <type>transmission_interface/SimpleTransmission</type>
    <joint name="left_wrist_flexor">
      <hardwareInterface>hardware_interface/EffortJointInterface</hardwareInterface>
    </joint>
    <actuator name="left_wrist_flexor_actr">
      <hardwareInterface>hardware_interface/EffortJointInterface</hardwareInterface>
      <mechanicalReduction>1</mechanicalReduction>
    </actuator>
  </transmission>
  <transmission name="right_shoulder_flexor_tran">
    <type>transmission_interface/SimpleTransmission</type>
    <joint name="right_shoulder_flexor">
      <hardwareInterface>hardware_interface/EffortJointInterface</hardwareInterface>
    </joint>
    <actuator name="right_shoulder_flexor_actr">
      <hardwareInterface>hardware_interface/EffortJointInterface</hardwareInterface>
      <mechanicalReduction>1</mechanicalReduction>
    </actuator>
  </transmission>
  <transmission name="right_shoulder_abductor_tran">
    <type>transmission_interface/SimpleTransmission</type>
    <joint name="right_shoulder_abductor">
      <hardwareInterface>hardware_interface/EffortJointInterface</hardwareInterface>
    </joint>
    <actuator name="right_shoulder_abductor_actr">
      <hardwareInterface>hardware_interface/EffortJointInterface</hardwareInterface>
      <mechanicalReduction>1</mechanicalReduction>
    </actuator>
  </transmission>
  <transmission name="right_arm_rotor0_tran">
    <type>transmission_interface/SimpleTransmission</type>
    <joint name="right_arm_rotor0">
      <hardwareInterface>hardware_interface/EffortJointInterface</hardwareInterface>
    </joint>
    <actuator name="right_arm_rotor0_actr">
      <hardwareInterface>hardware_interface/EffortJointInterface</hardwareInterface>
      <mechanicalReduction>1</mechanicalReduction>
    </actuator>
  </transmission>
  <transmission name="right_elbow_flexor_tran">
    <type>transmission_interface/SimpleTransmission</type>
    <joint name="right_elbow_flexor">
      <hardwareInterface>hardware_interface/EffortJointInterface</hardwareInterface>
    </joint>
    <actuator name="right_elbow_flexor_actr">
      <hardwareInterface>hardware_interface/EffortJointInterface</hardwareInterface>
      <mechanicalReduction>1</mechanicalReduction>
    </actuator>
  </transmission>
  <transmission name="right_arm_rotor1_tran">
    <type>transmission_interface/SimpleTransmission</type>
    <joint name="right_arm_rotor1">
      <hardwareInterface>hardware_interface/EffortJointInterface</hardwareInterface>
    </joint>
    <actuator name="right_arm_rotor1_actr">
      <hardwareInterface>hardware_interface/EffortJointInterface</hardwareInterface>
      <mechanicalReduction>1</mechanicalReduction>
    </actuator>
  </transmission>
  <transmission name="right_wrist_abductor_tran">
    <type>transmission_interface/SimpleTransmission</type>
    <joint name="right_wrist_abductor">
      <hardwareInterface>hardware_interface/EffortJointInterface</hardwareInterface>
    </joint>
    <actuator name="right_wrist_abductor_actr">
      <hardwareInterface>hardware_interface/EffortJointInterface</hardwareInterface>
      <mechanicalReduction>1</mechanicalReduction>
    </actuator>
  </transmission>
  <transmission name="right_wrist_flexor_tran">
    <type>transmission_interface/SimpleTransmission</type>
    <joint name="right_wrist_flexor">
      <hardwareInterface>hardware_interface/EffortJointInterface</hardwareInterface>
    </joint>
    <actuator name="right_wrist_flexor_actr">
      <hardwareInterface>hardware_interface/EffortJointInterface</hardwareInterface>
      <mechanicalReduction>1</mechanicalReduction>
    </actuator>
  </transmission>
  <transmission name="hip_rotor_tran">
    <type>transmission_interface/SimpleTransmission</type>
    <joint name="hip_rotor">
      <hardwareInterface>hardware_interface/EffortJointInterface</hardwareInterface>
    </joint>
    <actuator name="hip_rotor_actr">
      <hardwareInterface>hardware_interface/EffortJointInterface</hardwareInterface>
      <mechanicalReduction>1</mechanicalReduction>
    </actuator>
  </transmission>
  <transmission name="hip_abductor0_tran">
    <type>transmission_interface/SimpleTransmission</type>
    <joint name="hip_abductor0">
      <hardwareInterface>hardware_interface/EffortJointInterface</hardwareInterface>
    </joint>
    <actuator name="hip_abductor0_actr">
      <hardwareInterface>hardware_interface/EffortJointInterface</hardwareInterface>
      <mechanicalReduction>1</mechanicalReduction>
    </actuator>
  </transmission>
  <transmission name="left_leg_flexor_tran">
    <type>transmission_interface/SimpleTransmission</type>
    <joint name="left_leg_flexor">
      <hardwareInterface>hardware_interface/EffortJointInterface</hardwareInterface>
    </joint>
    <actuator name="left_leg_flexor_actr">
      <hardwareInterface>hardware_interface/EffortJointInterface</hardwareInterface>
      <mechanicalReduction>1</mechanicalReduction>
    </actuator>
  </transmission>
  <transmission name="right_leg_flexor_tran">
    <type>transmission_interface/SimpleTransmission</type>
    <joint name="right_leg_flexor">
      <hardwareInterface>hardware_interface/EffortJointInterface</hardwareInterface>
    </joint>
    <actuator name="right_leg_flexor_actr">
      <hardwareInterface>hardware_interface/EffortJointInterface</hardwareInterface>
      <mechanicalReduction>1</mechanicalReduction>
    </actuator>
  </transmission>
  <transmission name="right_leg_abductor_tran">
    <type>transmission_interface/SimpleTransmission</type>
    <joint name="right_leg_abductor">
      <hardwareInterface>hardware_interface/EffortJointInterface</hardwareInterface>
    </joint>
    <actuator name="right_leg_abductor_actr">
      <hardwareInterface>hardware_interface/EffortJointInterface</hardwareInterface>
      <mechanicalReduction>1</mechanicalReduction>
    </actuator>
  </transmission>
  <transmission name="left_leg_abductor_tran">
    <type>transmission_interface/SimpleTransmission</type>
    <joint name="left_leg_abductor">
      <hardwareInterface>hardware_interface/EffortJointInterface</hardwareInterface>
    </joint>
    <actuator name="left_leg_abductor_actr">
      <hardwareInterface>hardware_interface/EffortJointInterface</hardwareInterface>
      <mechanicalReduction>1</mechanicalReduction>
    </actuator>
  </transmission>
  <transmission name="left_leg_rotor_tran">
    <type>transmission_interface/SimpleTransmission</type>
    <joint name="left_leg_rotor">
      <hardwareInterface>hardware_interface/EffortJointInterface</hardwareInterface>
    </joint>
    <actuator name="left_leg_rotor_actr">
      <hardwareInterface>hardware_interface/EffortJointInterface</hardwareInterface>
      <mechanicalReduction>1</mechanicalReduction>
    </actuator>
  </transmission>
  <transmission name="right_leg_rotor_tran">
    <type>transmission_interface/SimpleTransmission</type>
    <joint name="right_leg_rotor">
      <hardwareInterface>hardware_interface/EffortJointInterface</hardwareInterface>
    </joint>
    <actuator name="right_leg_rotor_actr">
      <hardwareInterface>hardware_interface/EffortJointInterface</hardwareInterface>
      <mechanicalReduction>1</mechanicalReduction>
    </actuator>
  </transmission>
  <transmission name="left_knee_tran">
    <type>transmission_interface/SimpleTransmission</type>
    <joint name="left_knee">
      <hardwareInterface>hardware_interface/EffortJointInterface</hardwareInterface>
    </joint>
    <actuator name="left_knee_actr">
      <hardwareInterface>hardware_interface/EffortJointInterface</hardwareInterface>
      <mechanicalReduction>1</mechanicalReduction>
    </actuator>
  </transmission>
  <transmission name="right_knee_tran">
    <type>transmission_interface/SimpleTransmission</type>
    <joint name="right_knee">
      <hardwareInterface>hardware_interface/EffortJointInterface</hardwareInterface>
    </joint>
    <actuator name="right_knee_actr">
      <hardwareInterface>hardware_interface/EffortJointInterface</hardwareInterface>
      <mechanicalReduction>1</mechanicalReduction>
    </actuator>
  </transmission>
  <transmission name="left_ankle_roll_tran">
    <type>transmission_interface/SimpleTransmission</type>
    <joint name="left_ankle_roll">
      <hardwareInterface>hardware_interface/EffortJointInterface</hardwareInterface>
    </joint>
    <actuator name="left_ankle_roll_actr">
      <hardwareInterface>hardware_interface/EffortJointInterface</hardwareInterface>
      <mechanicalReduction>1</mechanicalReduction>
    </actuator>
  </transmission>
  <transmission name="right_ankle_roll_tran">
    <type>transmission_interface/SimpleTransmission</type>
    <joint name="right_ankle_roll">
      <hardwareInterface>hardware_interface/EffortJointInterface</hardwareInterface>
    </joint>
    <actuator name="right_ankle_roll_actr">
      <hardwareInterface>hardware_interface/EffortJointInterface</hardwareInterface>
      <mechanicalReduction>1</mechanicalReduction>
    </actuator>
  </transmission>
  <transmission name="right_ankle_pitch_tran">
    <type>transmission_interface/SimpleTransmission</type>
    <joint name="right_ankle_pitch">
      <hardwareInterface>hardware_interface/EffortJointInterface</hardwareInterface>
    </joint>
    <actuator name="right_ankle_pitch_actr">
      <hardwareInterface>hardware_interface/EffortJointInterface</hardwareInterface>
      <mechanicalReduction>1</mechanicalReduction>
    </actuator>
  </transmission>
  <transmission name="left_ankle_pitch_tran">
    <type>transmission_interface/SimpleTransmission</type>
    <joint name="left_ankle_pitch">
      <hardwareInterface>hardware_interface/EffortJointInterface</hardwareInterface>
    </joint>
    <actuator name="left_ankle_pitch_actr">
      <hardwareInterface>hardware_interface/EffortJointInterface</hardwareInterface>
      <mechanicalReduction>1</mechanicalReduction>
    </actuator>
  </transmission>
  <transmission name="left_leg_robstride_upper_tran">
    <type>transmission_interface/SimpleTransmission</type>
    <joint name="left_leg_robstride_upper">
      <hardwareInterface>hardware_interface/EffortJointInterface</hardwareInterface>
    </joint>
    <actuator name="left_leg_robstride_upper_actr">
      <hardwareInterface>hardware_interface/EffortJointInterface</hardwareInterface>
      <mechanicalReduction>1</mechanicalReduction>
    </actuator>
  </transmission>
  <transmission name="left_leg_robstride_lower_tran">
    <type>transmission_interface/SimpleTransmission</type>
    <joint name="left_leg_robstride_lower">
      <hardwareInterface>hardware_interface/EffortJointInterface</hardwareInterface>
    </joint>
    <actuator name="left_leg_robstride_lower_actr">
      <hardwareInterface>hardware_interface/EffortJointInterface</hardwareInterface>
      <mechanicalReduction>1</mechanicalReduction>
    </actuator>
  </transmission>
  <transmission name="right_leg_robstride_upper_tran">
    <type>transmission_interface/SimpleTransmission</type>
    <joint name="right_leg_robstride_upper">
      <hardwareInterface>hardware_interface/EffortJointInterface</hardwareInterface>
    </joint>
    <actuator name="right_leg_robstride_upper_actr">
      <hardwareInterface>hardware_interface/EffortJointInterface</hardwareInterface>
      <mechanicalReduction>1</mechanicalReduction>
    </actuator>
  </transmission>
  <transmission name="right_leg_robstride_lower_tran">
    <type>transmission_interface/SimpleTransmission</type>
    <joint name="right_leg_robstride_lower">
      <hardwareInterface>hardware_interface/EffortJointInterface</hardwareInterface>
    </joint>
    <actuator name="right_leg_robstride_lower_actr">
      <hardwareInterface>hardware_interface/EffortJointInterface</hardwareInterface>
      <mechanicalReduction>1</mechanicalReduction>
    </actuator>
  </transmission>
  <transmission name="neck_rotor_tran">
    <type>transmission_interface/SimpleTransmission</type>
    <joint name="neck_rotor">
      <hardwareInterface>hardware_interface/EffortJointInterface</hardwareInterface>
    </joint>
    <actuator name="neck_rotor_actr">
      <hardwareInterface>hardware_interface/EffortJointInterface</hardwareInterface>
      <mechanicalReduction>1</mechanicalReduction>
    </actuator>
  </transmission>
  <transmission name="neck_flexor_tran">
    <type>transmission_interface/SimpleTransmission</type>
    <joint name="neck_flexor">
      <hardwareInterface>hardware_interface/EffortJointInterface</hardwareInterface>
    </joint>
    <actuator name="neck_flexor_actr">
      <hardwareInterface>hardware_interface/EffortJointInterface</hardwareInterface>
      <mechanicalReduction>1</mechanicalReduction>
    </actuator>
  </transmission>
  <gazebo>
    <plugin filename="libgazebo_ros_control.so" name="control"/>
  </gazebo>
  <gazebo reference="base_link">
    <material>Gazebo/Silver</material>
    <mu1>0.2</mu1>
    <mu2>0.2</mu2>
    <self_collide>true</self_collide>
    <gravity>true</gravity>
  </gazebo>
  <gazebo reference="shoulder_upper_left_1">
    <material>Gazebo/Silver</material>
    <mu1>0.2</mu1>
    <mu2>0.2</mu2>
    <self_collide>true</self_collide>
  </gazebo>
  <gazebo reference="motor_2_left_1">
    <material>Gazebo/Silver</material>
    <mu1>0.2</mu1>
    <mu2>0.2</mu2>
    <self_collide>true</self_collide>
  </gazebo>
  <gazebo reference="shoulder_lower_left_1">
    <material>Gazebo/Silver</material>
    <mu1>0.2</mu1>
    <mu2>0.2</mu2>
    <self_collide>true</self_collide>
  </gazebo>
  <gazebo reference="motor_3_left_1">
    <material>Gazebo/Silver</material>
    <mu1>0.2</mu1>
    <mu2>0.2</mu2>
    <self_collide>true</self_collide>
  </gazebo>
  <gazebo reference="elbow_upper_left_1">
    <material>Gazebo/Silver</material>
    <mu1>0.2</mu1>
    <mu2>0.2</mu2>
    <self_collide>true</self_collide>
  </gazebo>
  <gazebo reference="motor_4_left_1">
    <material>Gazebo/Silver</material>
    <mu1>0.2</mu1>
    <mu2>0.2</mu2>
    <self_collide>true</self_collide>
  </gazebo>
  <gazebo reference="elbow_lower_left_1">
    <material>Gazebo/Silver</material>
    <mu1>0.2</mu1>
    <mu2>0.2</mu2>
    <self_collide>true</self_collide>
  </gazebo>
  <gazebo reference="motor_5_left_1">
    <material>Gazebo/Silver</material>
    <mu1>0.2</mu1>
    <mu2>0.2</mu2>
    <self_collide>true</self_collide>
  </gazebo>
  <gazebo reference="wrist_upper_left_1">
    <material>Gazebo/Silver</material>
    <mu1>0.2</mu1>
    <mu2>0.2</mu2>
    <self_collide>true</self_collide>
  </gazebo>
  <gazebo reference="motor_6_left_1">
    <material>Gazebo/Silver</material>
    <mu1>0.2</mu1>
    <mu2>0.2</mu2>
    <self_collide>true</self_collide>
  </gazebo>
  <gazebo reference="wrist_lower_left_1">
    <material>Gazebo/Silver</material>
    <mu1>0.2</mu1>
    <mu2>0.2</mu2>
    <self_collide>true</self_collide>
  </gazebo>
  <gazebo reference="motor_7_left_1">
    <material>Gazebo/Silver</material>
    <mu1>0.2</mu1>
    <mu2>0.2</mu2>
    <self_collide>true</self_collide>
  </gazebo>
  <gazebo reference="eef_left_1">
    <material>Gazebo/Silver</material>
    <mu1>0.2</mu1>
    <mu2>0.2</mu2>
    <self_collide>true</self_collide>
  </gazebo>
  <gazebo reference="shoulder_upper_right_1">
    <material>Gazebo/Silver</material>
    <mu1>0.2</mu1>
    <mu2>0.2</mu2>
    <self_collide>true</self_collide>
  </gazebo>
  <gazebo reference="motor_2_right_1">
    <material>Gazebo/Silver</material>
    <mu1>0.2</mu1>
    <mu2>0.2</mu2>
    <self_collide>true</self_collide>
  </gazebo>
  <gazebo reference="shoulder_lower_right_1">
    <material>Gazebo/Silver</material>
    <mu1>0.2</mu1>
    <mu2>0.2</mu2>
    <self_collide>true</self_collide>
  </gazebo>
  <gazebo reference="motor_3_right_1">
    <material>Gazebo/Silver</material>
    <mu1>0.2</mu1>
    <mu2>0.2</mu2>
    <self_collide>true</self_collide>
  </gazebo>
  <gazebo reference="elbow_upper_right_1">
    <material>Gazebo/Silver</material>
    <mu1>0.2</mu1>
    <mu2>0.2</mu2>
    <self_collide>true</self_collide>
  </gazebo>
  <gazebo reference="motor_4_right_1">
    <material>Gazebo/Silver</material>
    <mu1>0.2</mu1>
    <mu2>0.2</mu2>
    <self_collide>true</self_collide>
  </gazebo>
  <gazebo reference="elbow_lower_right_1">
    <material>Gazebo/Silver</material>
    <mu1>0.2</mu1>
    <mu2>0.2</mu2>
    <self_collide>true</self_collide>
  </gazebo>
  <gazebo reference="motor_5_right_1">
    <material>Gazebo/Silver</material>
    <mu1>0.2</mu1>
    <mu2>0.2</mu2>
    <self_collide>true</self_collide>
  </gazebo>
  <gazebo reference="wrist_upper_right_1">
    <material>Gazebo/Silver</material>
    <mu1>0.2</mu1>
    <mu2>0.2</mu2>
    <self_collide>true</self_collide>
  </gazebo>
  <gazebo reference="motor_6_right_1">
    <material>Gazebo/Silver</material>
    <mu1>0.2</mu1>
    <mu2>0.2</mu2>
    <self_collide>true</self_collide>
  </gazebo>
  <gazebo reference="wrist_lower_right_1">
    <material>Gazebo/Silver</material>
    <mu1>0.2</mu1>
    <mu2>0.2</mu2>
    <self_collide>true</self_collide>
  </gazebo>
  <gazebo reference="motor_7_right_1">
    <material>Gazebo/Silver</material>
    <mu1>0.2</mu1>
    <mu2>0.2</mu2>
    <self_collide>true</self_collide>
  </gazebo>
  <gazebo reference="eef_right_1">
    <material>Gazebo/Silver</material>
    <mu1>0.2</mu1>
    <mu2>0.2</mu2>
    <self_collide>true</self_collide>
  </gazebo>
  <gazebo reference="motor_1_right_1">
    <material>Gazebo/Silver</material>
    <mu1>0.2</mu1>
    <mu2>0.2</mu2>
    <self_collide>true</self_collide>
  </gazebo>
  <gazebo reference="motor_1_left_1">
    <material>Gazebo/Silver</material>
    <mu1>0.2</mu1>
    <mu2>0.2</mu2>
    <self_collide>true</self_collide>
  </gazebo>
  <gazebo reference="rotor_waist_1">
    <material>Gazebo/Silver</material>
    <mu1>0.2</mu1>
    <mu2>0.2</mu2>
    <self_collide>true</self_collide>
  </gazebo>
  <gazebo reference="Middle_Connector_Platre_1">
    <material>Gazebo/Silver</material>
    <mu1>0.2</mu1>
    <mu2>0.2</mu2>
    <self_collide>true</self_collide>
  </gazebo>
  <gazebo reference="abductor_central_1">
    <material>Gazebo/Silver</material>
    <mu1>0.2</mu1>
    <mu2>0.2</mu2>
    <self_collide>true</self_collide>
  </gazebo>
  <gazebo reference="hip_subframe_1">
    <material>Gazebo/Silver</material>
    <mu1>0.2</mu1>
    <mu2>0.2</mu2>
    <self_collide>true</self_collide>
  </gazebo>
  <gazebo reference="flexor_right_1">
    <material>Gazebo/Silver</material>
    <mu1>0.2</mu1>
    <mu2>0.2</mu2>
    <self_collide>true</self_collide>
  </gazebo>
  <gazebo reference="flexor_left_1">
    <material>Gazebo/Silver</material>
    <mu1>0.2</mu1>
    <mu2>0.2</mu2>
    <self_collide>true</self_collide>
  </gazebo>
  <gazebo reference="flexor_plate_left_1">
    <material>Gazebo/Silver</material>
    <mu1>0.2</mu1>
    <mu2>0.2</mu2>
    <self_collide>true</self_collide>
  </gazebo>
  <gazebo reference="flexor_plate_right_1">
    <material>Gazebo/Silver</material>
    <mu1>0.2</mu1>
    <mu2>0.2</mu2>
    <self_collide>true</self_collide>
  </gazebo>
  <gazebo reference="abductor_right_1">
    <material>Gazebo/Silver</material>
    <mu1>0.2</mu1>
    <mu2>0.2</mu2>
    <self_collide>true</self_collide>
  </gazebo>
  <gazebo reference="abductor_left_1">
    <material>Gazebo/Silver</material>
    <mu1>0.2</mu1>
    <mu2>0.2</mu2>
    <self_collide>true</self_collide>
  </gazebo>
  <gazebo reference="femural_head_left_1">
    <material>Gazebo/Silver</material>
    <mu1>0.2</mu1>
    <mu2>0.2</mu2>
    <self_collide>true</self_collide>
  </gazebo>
  <gazebo reference="femural_head_right_1">
    <material>Gazebo/Silver</material>
    <mu1>0.2</mu1>
    <mu2>0.2</mu2>
    <self_collide>true</self_collide>
  </gazebo>
  <gazebo reference="rotor_right_1">
    <material>Gazebo/Silver</material>
    <mu1>0.2</mu1>
    <mu2>0.2</mu2>
    <self_collide>true</self_collide>
  </gazebo>
  <gazebo reference="rotor_left_1">
    <material>Gazebo/Silver</material>
    <mu1>0.2</mu1>
    <mu2>0.2</mu2>
    <self_collide>true</self_collide>
  </gazebo>
  <gazebo reference="femur_left_1">
    <material>Gazebo/Silver</material>
    <mu1>0.2</mu1>
    <mu2>0.2</mu2>
    <self_collide>true</self_collide>
  </gazebo>
  <gazebo reference="femur_right_1">
    <material>Gazebo/Silver</material>
    <mu1>0.2</mu1>
    <mu2>0.2</mu2>
    <self_collide>true</self_collide>
  </gazebo>
  <gazebo reference="knee_right_1">
    <material>Gazebo/Silver</material>
    <mu1>0.2</mu1>
    <mu2>0.2</mu2>
    <self_collide>true</self_collide>
  </gazebo>
  <gazebo reference="knee_left_1">
    <material>Gazebo/Silver</material>
    <mu1>0.2</mu1>
    <mu2>0.2</mu2>
    <self_collide>true</self_collide>
  </gazebo>
  <gazebo reference="ankle_actuator_upper_right_1">
    <material>Gazebo/Silver</material>
    <mu1>0.2</mu1>
    <mu2>0.2</mu2>
    <self_collide>true</self_collide>
  </gazebo>
  <gazebo reference="ankle_actuator_lower_right_1">
    <material>Gazebo/Silver</material>
    <mu1>0.2</mu1>
    <mu2>0.2</mu2>
    <self_collide>true</self_collide>
  </gazebo>
  <gazebo reference="ankle_actuator_upper_left_1">
    <material>Gazebo/Silver</material>
    <mu1>0.2</mu1>
    <mu2>0.2</mu2>
    <self_collide>true</self_collide>
  </gazebo>
  <gazebo reference="ankle_actuator_lower_left_1">
    <material>Gazebo/Silver</material>
    <mu1>0.2</mu1>
    <mu2>0.2</mu2>
    <self_collide>true</self_collide>
  </gazebo>
  <gazebo reference="tibia_subframe_left_1">
    <material>Gazebo/Silver</material>
    <mu1>0.2</mu1>
    <mu2>0.2</mu2>
    <self_collide>true</self_collide>
  </gazebo>
  <gazebo reference="tibia_subframe_right_1">
    <material>Gazebo/Silver</material>
    <mu1>0.2</mu1>
    <mu2>0.2</mu2>
    <self_collide>true</self_collide>
  </gazebo>
  <gazebo reference="ankle_spherical_joint_left_1">
    <material>Gazebo/Silver</material>
    <mu1>0.2</mu1>
    <mu2>0.2</mu2>
    <self_collide>true</self_collide>
  </gazebo>
  <gazebo reference="ankle_spherical_joint_right_1">
    <material>Gazebo/Silver</material>
    <mu1>0.2</mu1>
    <mu2>0.2</mu2>
    <self_collide>true</self_collide>
  </gazebo>
  <gazebo reference="foot_right_1">
    <material>Gazebo/Silver</material>
    <mu1>0.2</mu1>
    <mu2>0.2</mu2>
    <self_collide>true</self_collide>
  </gazebo>
  <gazebo reference="foot_left_1">
    <material>Gazebo/Silver</material>
    <mu1>0.2</mu1>
    <mu2>0.2</mu2>
    <self_collide>true</self_collide>
  </gazebo>
  <gazebo reference="upper_plate_right_1">
    <material>Gazebo/Silver</material>
    <mu1>0.2</mu1>
    <mu2>0.2</mu2>
    <self_collide>true</self_collide>
  </gazebo>
  <gazebo reference="lower_plate_right_1">
    <material>Gazebo/Silver</material>
    <mu1>0.2</mu1>
    <mu2>0.2</mu2>
    <self_collide>true</self_collide>
  </gazebo>
  <gazebo reference="upper_plate_left_1">
    <material>Gazebo/Silver</material>
    <mu1>0.2</mu1>
    <mu2>0.2</mu2>
    <self_collide>true</self_collide>
  </gazebo>
  <gazebo reference="lower_plate_left_1">
    <material>Gazebo/Silver</material>
    <mu1>0.2</mu1>
    <mu2>0.2</mu2>
    <self_collide>true</self_collide>
  </gazebo>
  <gazebo reference="rotor_neck_1">
    <material>Gazebo/Silver</material>
    <mu1>0.2</mu1>
    <mu2>0.2</mu2>
    <self_collide>true</self_collide>
  </gazebo>
  <gazebo reference="neck_connector_plate_1">
    <material>Gazebo/Silver</material>
    <mu1>0.2</mu1>
    <mu2>0.2</mu2>
    <self_collide>true</self_collide>
  </gazebo>
  <gazebo reference="flexor_neck_1">
    <material>Gazebo/Silver</material>
    <mu1>0.2</mu1>
    <mu2>0.2</mu2>
    <self_collide>true</self_collide>
  </gazebo>
  <gazebo reference="head_1">
    <material>Gazebo/Silver</material>
    <mu1>0.2</mu1>
    <mu2>0.2</mu2>
    <self_collide>true</self_collide>
  </gazebo>
  <link name="base_link">
    <inertial>
      <origin rpy="0 0 0" xyz="0.0039597851560642635 0.031650293425042234 0.04513635127571502"/>
      <mass value="5.04389786724998"/>
      <inertia ixx="1.044816" ixy="0.003133" ixz="-0.000737" iyy="1.301227" iyz="-0.089265" izz="0.854226"/>
    </inertial>
    <visual>
      <origin rpy="0 0 0" xyz="0 0 0"/>
      <geometry>
        <mesh filename="file:///home/ubuntu/ethr_rc_robot_assets/humanoid-description/humanoid_final_copy_description/meshes/base_link.stl" scale="0.001 0.001 0.001"/>
      </geometry>
      <material name="silver"/>
    </visual>
    <collision>
      <origin rpy="0 0 0" xyz="0 0 0"/>
      <geometry>
        <mesh filename="file:///home/ubuntu/ethr_rc_robot_assets/humanoid-description/humanoid_final_copy_description/meshes/base_link.stl" scale="0.001 0.001 0.001"/>
      </geometry>
    </collision>
  </link>
  <link name="shoulder_upper_left_1">
    <inertial>
      <origin rpy="0 0 0" xyz="0.029371582426431952 0.011455819614883442 -0.0006489592343114359"/>
      <mass value="0.08262280420588444"/>
      <inertia ixx="8.2e-05" ixy="-2.3e-05" ixz="8e-06" iyy="0.000114" iyz="-8e-06" izz="0.000115"/>
    </inertial>
    <visual>
      <origin rpy="0 0 0" xyz="-0.199791 -0.054809 -0.230171"/>
      <geometry>
        <mesh filename="file:///home/ubuntu/ethr_rc_robot_assets/humanoid-description/humanoid_final_copy_description/meshes/shoulder_upper_left_1.stl" scale="0.001 0.001 0.001"/>
      </geometry>
      <material name="silver"/>
    </visual>
    <collision>
      <origin rpy="0 0 0" xyz="-0.199791 -0.054809 -0.230171"/>
      <geometry>
        <mesh filename="file:///home/ubuntu/ethr_rc_robot_assets/humanoid-description/humanoid_final_copy_description/meshes/shoulder_upper_left_1.stl" scale="0.001 0.001 0.001"/>
      </geometry>
    </collision>
  </link>
  <link name="motor_2_left_1">
    <inertial>
      <origin rpy="0 0 0" xyz="0.3077198879097538 -0.04959845490599223 -0.19041903903936902"/>
      <mass value="0.570"/>
      <inertia ixx="0.002086" ixy="9e-06" ixz="1.2e-05" iyy="0.001913" iyz="-4.1e-05" izz="0.002038"/>
    </inertial>
    <visual>
      <origin rpy="0 0 0" xyz="0.06006 -0.100063 -0.434577"/>
      <geometry>
        <mesh filename="file:///home/ubuntu/ethr_rc_robot_assets/humanoid-description/humanoid_final_copy_description/meshes/motor_2_left_1.stl" scale="0.001 0.001 0.001"/>
      </geometry>
      <material name="silver"/>
    </visual>
    <collision>
      <origin rpy="0 0 0" xyz="0.06006 -0.100063 -0.434577"/>
      <geometry>
        <mesh filename="file:///home/ubuntu/ethr_rc_robot_assets/humanoid-description/humanoid_final_copy_description/meshes/motor_2_left_1.stl" scale="0.001 0.001 0.001"/>
      </geometry>
    </collision>
  </link>
  <link name="shoulder_lower_left_1">
    <inertial>
      <origin rpy="0 0 0" xyz="0.007032518249487085 -0.004482753146523246 -0.0330470290895766"/>
      <mass value="0.036136830024378175"/>
      <inertia ixx="3e-05" ixy="-1e-06" ixz="3e-06" iyy="3.1e-05" iyz="3e-06" izz="1.6e-05"/>
    </inertial>
    <visual>
      <origin rpy="0 0 0" xyz="-0.243413 -0.015939 -0.262343"/>
      <geometry>
        <mesh filename="file:///home/ubuntu/ethr_rc_robot_assets/humanoid-description/humanoid_final_copy_description/meshes/shoulder_lower_left_1.stl" scale="0.001 0.001 0.001"/>
      </geometry>
      <material name="silver"/>
    </visual>
    <collision>
      <origin rpy="0 0 0" xyz="-0.243413 -0.015939 -0.262343"/>
      <geometry>
        <mesh filename="file:///home/ubuntu/ethr_rc_robot_assets/humanoid-description/humanoid_final_copy_description/meshes/shoulder_lower_left_1.stl" scale="0.001 0.001 0.001"/>
      </geometry>
    </collision>
  </link>
  <link name="motor_3_left_1">
    <inertial>
      <origin rpy="0 0 0" xyz="0.005551050466483853 -0.01602113463031391 -0.026854699989131342"/>
      <mass value="0.570"/>
      <inertia ixx="0.000663" ixy="4e-06" ixz="6e-06" iyy="0.000645" iyz="-1.7e-05" izz="0.000627"/>
    </inertial>
    <visual>
      <origin rpy="0 0 0" xyz="-0.256232 -0.023115 -0.202865"/>
      <geometry>
        <mesh filename="file:///home/ubuntu/ethr_rc_robot_assets/humanoid-description/humanoid_final_copy_description/meshes/motor_3_left_1.stl" scale="0.001 0.001 0.001"/>
      </geometry>
      <material name="silver"/>
    </visual>
    <collision>
      <origin rpy="0 0 0" xyz="-0.256232 -0.023115 -0.202865"/>
      <geometry>
        <mesh filename="file:///home/ubuntu/ethr_rc_robot_assets/humanoid-description/humanoid_final_copy_description/meshes/motor_3_left_1.stl" scale="0.001 0.001 0.001"/>
      </geometry>
    </collision>
  </link>
  <link name="elbow_upper_left_1">
    <inertial>
      <origin rpy="0 0 0" xyz="0.016535727012897072 -0.04747096966805564 -0.02304096593636086"/>
      <mass value="0.10404444315750117"/>
      <inertia ixx="0.000191" ixy="-1e-06" ixz="-1.2e-05" iyy="0.000208" iyz="-4.5e-05" izz="0.000153"/>
    </inertial>
    <visual>
      <origin rpy="0 0 0" xyz="-0.254187 -0.017133 -0.135735"/>
      <geometry>
        <mesh filename="file:///home/ubuntu/ethr_rc_robot_assets/humanoid-description/humanoid_final_copy_description/meshes/elbow_upper_left_1.stl" scale="0.001 0.001 0.001"/>
      </geometry>
      <material name="silver"/>
    </visual>
    <collision>
      <origin rpy="0 0 0" xyz="-0.254187 -0.017133 -0.135735"/>
      <geometry>
        <mesh filename="file:///home/ubuntu/ethr_rc_robot_assets/humanoid-description/humanoid_final_copy_description/meshes/elbow_upper_left_1.stl" scale="0.001 0.001 0.001"/>
      </geometry>
    </collision>
  </link>
  <link name="motor_4_left_1">
    <inertial>
      <origin rpy="0 0 0" xyz="0.026601340247465355 -0.032357152031103134 0.005942454298567927"/>
      <mass value="0.570"/>
      <inertia ixx="0.000618" ixy="-1e-06" ixz="-1.1e-05" iyy="0.000657" iyz="3e-06" izz="0.00066"/>
    </inertial>
    <visual>
      <origin rpy="0 0 0" xyz="-0.259849 0.033689 -0.048187"/>
      <geometry>
        <mesh filename="file:///home/ubuntu/ethr_rc_robot_assets/humanoid-description/humanoid_final_copy_description/meshes/motor_4_left_1.stl" scale="0.001 0.001 0.001"/>
      </geometry>
      <material name="silver"/>
    </visual>
    <collision>
      <origin rpy="0 0 0" xyz="-0.259849 0.033689 -0.048187"/>
      <geometry>
        <mesh filename="file:///home/ubuntu/ethr_rc_robot_assets/humanoid-description/humanoid_final_copy_description/meshes/motor_4_left_1.stl" scale="0.001 0.001 0.001"/>
      </geometry>
    </collision>
  </link>
  <link name="elbow_lower_left_1">
    <inertial>
      <origin rpy="0 0 0" xyz="-0.003895699693225285 -0.013998793555563396 -0.024949701442376904"/>
      <mass value="0.03799090103546687"/>
      <inertia ixx="3.6e-05" ixy="-4e-06" ixz="-6e-06" iyy="3e-05" iyz="0.0" izz="2.9e-05"/>
    </inertial>
    <visual>
      <origin rpy="0 0 0" xyz="-0.317505 0.066303 -0.060777"/>
      <geometry>
        <mesh filename="file:///home/ubuntu/ethr_rc_robot_assets/humanoid-description/humanoid_final_copy_description/meshes/elbow_lower_left_1.stl" scale="0.001 0.001 0.001"/>
      </geometry>
      <material name="silver"/>
    </visual>
    <collision>
      <origin rpy="0 0 0" xyz="-0.317505 0.066303 -0.060777"/>
      <geometry>
        <mesh filename="file:///home/ubuntu/ethr_rc_robot_assets/humanoid-description/humanoid_final_copy_description/meshes/elbow_lower_left_1.stl" scale="0.001 0.001 0.001"/>
      </geometry>
    </collision>
  </link>
  <link name="motor_5_left_1">
    <inertial>
      <origin rpy="0 0 0" xyz="0.008455686990776534 0.013654843597576224 -0.03910604462778203"/>
      <mass value="0.570"/>
      <inertia ixx="0.000655" ixy="5e-06" ixz="5e-06" iyy="0.000651" iyz="-2.1e-05" izz="0.00063"/>
    </inertial>
    <visual>
      <origin rpy="0 0 0" xyz="-0.289633 0.118222 -0.028792"/>
      <geometry>
        <mesh filename="file:///home/ubuntu/ethr_rc_robot_assets/humanoid-description/humanoid_final_copy_description/meshes/motor_5_left_1.stl" scale="0.001 0.001 0.001"/>
      </geometry>
      <material name="silver"/>
    </visual>
    <collision>
      <origin rpy="0 0 0" xyz="-0.289633 0.118222 -0.028792"/>
      <geometry>
        <mesh filename="file:///home/ubuntu/ethr_rc_robot_assets/humanoid-description/humanoid_final_copy_description/meshes/motor_5_left_1.stl" scale="0.001 0.001 0.001"/>
      </geometry>
    </collision>
  </link>
  <link name="wrist_upper_left_1">
    <inertial>
      <origin rpy="0 0 0" xyz="0.0026881032563236262 -0.0028429793311608165 -0.012815610297392803"/>
      <mass value="0.031126167143252285"/>
      <inertia ixx="2.2e-05" ixy="-1e-06" ixz="1e-06" iyy="2.4e-05" iyz="3e-06" izz="2e-05"/>
    </inertial>
    <visual>
      <origin rpy="0 0 0" xyz="-0.303724 0.120673 0.0371"/>
      <geometry>
        <mesh filename="file:///home/ubuntu/ethr_rc_robot_assets/humanoid-description/humanoid_final_copy_description/meshes/wrist_upper_left_1.stl" scale="0.001 0.001 0.001"/>
      </geometry>
      <material name="silver"/>
    </visual>
    <collision>
      <origin rpy="0 0 0" xyz="-0.303724 0.120673 0.0371"/>
      <geometry>
        <mesh filename="file:///home/ubuntu/ethr_rc_robot_assets/humanoid-description/humanoid_final_copy_description/meshes/wrist_upper_left_1.stl" scale="0.001 0.001 0.001"/>
      </geometry>
    </collision>
  </link>
  <link name="motor_6_left_1">
    <inertial>
      <origin rpy="0 0 0" xyz="0.026796384446887422 -0.03216427196459663 0.0059431274071075485"/>
      <mass value="0.570"/>
      <inertia ixx="0.000656" ixy="-5e-06" ixz="0.0" iyy="0.000627" iyz="2e-05" izz="0.000653"/>
    </inertial>
    <visual>
      <origin rpy="0 0 0" xyz="-0.284257 0.113162 0.078158"/>
      <geometry>
        <mesh filename="file:///home/ubuntu/ethr_rc_robot_assets/humanoid-description/humanoid_final_copy_description/meshes/motor_6_left_1.stl" scale="0.001 0.001 0.001"/>
      </geometry>
      <material name="silver"/>
    </visual>
    <collision>
      <origin rpy="0 0 0" xyz="-0.284257 0.113162 0.078158"/>
      <geometry>
        <mesh filename="file:///home/ubuntu/ethr_rc_robot_assets/humanoid-description/humanoid_final_copy_description/meshes/motor_6_left_1.stl" scale="0.001 0.001 0.001"/>
      </geometry>
    </collision>
  </link>
  <link name="wrist_lower_left_1">
    <inertial>
      <origin rpy="0 0 0" xyz="0.005534479206150966 -0.021710003923659627 -0.047316235899459345"/>
      <mass value="0.05108485525996972"/>
      <inertia ixx="7.1e-05" ixy="6e-06" ixz="6e-06" iyy="7.1e-05" iyz="-1.8e-05" izz="3.3e-05"/>
    </inertial>
    <visual>
      <origin rpy="0 0 0" xyz="-0.307348 0.172729 0.056593"/>
      <geometry>
        <mesh filename="file:///home/ubuntu/ethr_rc_robot_assets/humanoid-description/humanoid_final_copy_description/meshes/wrist_lower_left_1.stl" scale="0.001 0.001 0.001"/>
      </geometry>
      <material name="silver"/>
    </visual>
    <collision>
      <origin rpy="0 0 0" xyz="-0.307348 0.172729 0.056593"/>
      <geometry>
        <mesh filename="file:///home/ubuntu/ethr_rc_robot_assets/humanoid-description/humanoid_final_copy_description/meshes/wrist_lower_left_1.stl" scale="0.001 0.001 0.001"/>
      </geometry>
    </collision>
  </link>
  <link name="motor_7_left_1">
    <inertial>
      <origin rpy="0 0 0" xyz="-0.012580888508910815 -0.01607944521488236 -0.030911555528650714"/>
      <mass value="0.570"/>
      <inertia ixx="0.000618" ixy="-1e-06" ixz="-1.1e-05" iyy="0.000657" iyz="3e-06" izz="0.00066"/>
    </inertial>
    <visual>
      <origin rpy="0 0 0" xyz="-0.338511 0.16397 0.104879"/>
      <geometry>
        <mesh filename="file:///home/ubuntu/ethr_rc_robot_assets/humanoid-description/humanoid_final_copy_description/meshes/motor_7_left_1.stl" scale="0.001 0.001 0.001"/>
      </geometry>
      <material name="silver"/>
    </visual>
    <collision>
      <origin rpy="0 0 0" xyz="-0.338511 0.16397 0.104879"/>
      <geometry>
        <mesh filename="file:///home/ubuntu/ethr_rc_robot_assets/humanoid-description/humanoid_final_copy_description/meshes/motor_7_left_1.stl" scale="0.001 0.001 0.001"/>
      </geometry>
    </collision>
  </link>
  <link name="eef_left_1">
    <inertial>
      <origin rpy="0 0 0" xyz="-0.01163988406690325 -0.03408251587669356 -0.06231409906835733"/>
      <mass value="0.3310419386053802"/>
      <inertia ixx="0.00022" ixy="-1.6e-05" ixz="-3.1e-05" iyy="0.000208" iyz="-4.2e-05" izz="0.00015"/>
    </inertial>
    <visual>
      <origin rpy="0 0 0" xyz="-0.356985 0.180306 0.129143"/>
      <geometry>
        <mesh filename="file:///home/ubuntu/ethr_rc_robot_assets/humanoid-description/humanoid_final_copy_description/meshes/eef_left_1.stl" scale="0.001 0.001 0.001"/>
      </geometry>
      <material name="silver"/>
    </visual>
    <collision>
      <origin rpy="0 0 0" xyz="-0.356985 0.180306 0.129143"/>
      <geometry>
        <mesh filename="file:///home/ubuntu/ethr_rc_robot_assets/humanoid-description/humanoid_final_copy_description/meshes/eef_left_1.stl" scale="0.001 0.001 0.001"/>
      </geometry>
    </collision>
  </link>
  <link name="shoulder_upper_right_1">
    <inertial>
      <origin rpy="0 0 0" xyz="-0.029094377134725374 0.01213737944080008 -0.0007429911551526669"/>
      <mass value="0.08262280420588453"/>
      <inertia ixx="8.4e-05" ixy="2.4e-05" ixz="-9e-06" iyy="0.000113" iyz="-8e-06" izz="0.000115"/>
    </inertial>
    <visual>
      <origin rpy="0 0 0" xyz="0.191872 -0.059375 -0.229541"/>
      <geometry>
        <mesh filename="file:///home/ubuntu/ethr_rc_robot_assets/humanoid-description/humanoid_final_copy_description/meshes/shoulder_upper_right_1.stl" scale="0.001 0.001 0.001"/>
      </geometry>
      <material name="silver"/>
    </visual>
    <collision>
      <origin rpy="0 0 0" xyz="0.191872 -0.059375 -0.229541"/>
      <geometry>
        <mesh filename="file:///home/ubuntu/ethr_rc_robot_assets/humanoid-description/humanoid_final_copy_description/meshes/shoulder_upper_right_1.stl" scale="0.001 0.001 0.001"/>
      </geometry>
    </collision>
  </link>
  <link name="motor_2_right_1">
    <inertial>
      <origin rpy="0 0 0" xyz="0.18795901841149557 0.1758311624468456 0.11333274048365377"/>
      <mass value="0.570"/>
      <inertia ixx="0.002085" ixy="-1.2e-05" ixz="-1.2e-05" iyy="0.001914" iyz="-4.1e-05" izz="0.002037"/>
    </inertial>
    <visual>
      <origin rpy="0 0 0" xyz="0.427833 0.119683 -0.130041"/>
      <geometry>
        <mesh filename="file:///home/ubuntu/ethr_rc_robot_assets/humanoid-description/humanoid_final_copy_description/meshes/motor_2_right_1.stl" scale="0.001 0.001 0.001"/>
      </geometry>
      <material name="silver"/>
    </visual>
    <collision>
      <origin rpy="0 0 0" xyz="0.427833 0.119683 -0.130041"/>
      <geometry>
        <mesh filename="file:///home/ubuntu/ethr_rc_robot_assets/humanoid-description/humanoid_final_copy_description/meshes/motor_2_right_1.stl" scale="0.001 0.001 0.001"/>
      </geometry>
    </collision>
  </link>
  <link name="shoulder_lower_right_1">
    <inertial>
      <origin rpy="0 0 0" xyz="-0.007028420602658153 -0.004318146060636682 -0.03306957274188846"/>
      <mass value="0.036136830024378175"/>
      <inertia ixx="3e-05" ixy="1e-06" ixz="-3e-06" iyy="3.1e-05" iyz="3e-06" izz="1.6e-05"/>
    </inertial>
    <visual>
      <origin rpy="0 0 0" xyz="0.236492 -0.021533 -0.261571"/>
      <geometry>
        <mesh filename="file:///home/ubuntu/ethr_rc_robot_assets/humanoid-description/humanoid_final_copy_description/meshes/shoulder_lower_right_1.stl" scale="0.001 0.001 0.001"/>
      </geometry>
      <material name="silver"/>
    </visual>
    <collision>
      <origin rpy="0 0 0" xyz="0.236492 -0.021533 -0.261571"/>
      <geometry>
        <mesh filename="file:///home/ubuntu/ethr_rc_robot_assets/humanoid-description/humanoid_final_copy_description/meshes/shoulder_lower_right_1.stl" scale="0.001 0.001 0.001"/>
      </geometry>
    </collision>
  </link>
  <link name="motor_3_right_1">
    <inertial>
      <origin rpy="0 0 0" xyz="-0.005837118122776042 -0.015888012038720648 -0.026873586883889078"/>
      <mass value="0.570"/>
      <inertia ixx="0.000663" ixy="-4e-06" ixz="-7e-06" iyy="0.000645" iyz="-1.7e-05" izz="0.000627"/>
    </inertial>
    <visual>
      <origin rpy="0 0 0" xyz="0.248948 -0.029004 -0.202053"/>
      <geometry>
        <mesh filename="file:///home/ubuntu/ethr_rc_robot_assets/humanoid-description/humanoid_final_copy_description/meshes/motor_3_right_1.stl" scale="0.001 0.001 0.001"/>
      </geometry>
      <material name="silver"/>
    </visual>
    <collision>
      <origin rpy="0 0 0" xyz="0.248948 -0.029004 -0.202053"/>
      <geometry>
        <mesh filename="file:///home/ubuntu/ethr_rc_robot_assets/humanoid-description/humanoid_final_copy_description/meshes/motor_3_right_1.stl" scale="0.001 0.001 0.001"/>
      </geometry>
    </collision>
  </link>
  <link name="elbow_upper_right_1">
    <inertial>
      <origin rpy="0 0 0" xyz="0.008585711702110421 0.0004583377089432128 -0.05705069622296509"/>
      <mass value="0.10404444315750118"/>
      <inertia ixx="0.000191" ixy="2e-06" ixz="1.1e-05" iyy="0.000208" iyz="-4.5e-05" izz="0.000153"/>
    </inertial>
    <visual>
      <origin rpy="0 0 0" xyz="0.272977 0.024558 -0.168884"/>
      <geometry>
        <mesh filename="file:///home/ubuntu/ethr_rc_robot_assets/humanoid-description/humanoid_final_copy_description/meshes/elbow_upper_right_1.stl" scale="0.001 0.001 0.001"/>
      </geometry>
      <material name="silver"/>
    </visual>
    <collision>
      <origin rpy="0 0 0" xyz="0.272977 0.024558 -0.168884"/>
      <geometry>
        <mesh filename="file:///home/ubuntu/ethr_rc_robot_assets/humanoid-description/humanoid_final_copy_description/meshes/elbow_upper_right_1.stl" scale="0.001 0.001 0.001"/>
      </geometry>
    </collision>
  </link>
  <link name="motor_4_right_1">
    <inertial>
      <origin rpy="0 0 0" xyz="-0.03290063731495149 -0.015795692347778244 -0.021338885525285393"/>
      <mass value="0.570"/>
      <inertia ixx="0.000618" ixy="2e-06" ixz="1.1e-05" iyy="0.000657" iyz="3e-06" izz="0.00066"/>
    </inertial>
    <visual>
      <origin rpy="0 0 0" xyz="0.247858 0.043638 -0.074556"/>
      <geometry>
        <mesh filename="file:///home/ubuntu/ethr_rc_robot_assets/humanoid-description/humanoid_final_copy_description/meshes/motor_4_right_1.stl" scale="0.001 0.001 0.001"/>
      </geometry>
      <material name="silver"/>
    </visual>
    <collision>
      <origin rpy="0 0 0" xyz="0.247858 0.043638 -0.074556"/>
      <geometry>
        <mesh filename="file:///home/ubuntu/ethr_rc_robot_assets/humanoid-description/humanoid_final_copy_description/meshes/motor_4_right_1.stl" scale="0.001 0.001 0.001"/>
      </geometry>
    </collision>
  </link>
  <link name="elbow_lower_right_1">
    <inertial>
      <origin rpy="0 0 0" xyz="0.003648476172679771 -0.014086993018150383 -0.024936854494651203"/>
      <mass value="0.037990901035467844"/>
      <inertia ixx="3.6e-05" ixy="4e-06" ixz="6e-06" iyy="3e-05" iyz="0.0" izz="2.9e-05"/>
    </inertial>
    <visual>
      <origin rpy="0 0 0" xyz="0.311832 0.058966 -0.059764"/>
      <geometry>
        <mesh filename="file:///home/ubuntu/ethr_rc_robot_assets/humanoid-description/humanoid_final_copy_description/meshes/elbow_lower_right_1.stl" scale="0.001 0.001 0.001"/>
      </geometry>
      <material name="silver"/>
    </visual>
    <collision>
      <origin rpy="0 0 0" xyz="0.311832 0.058966 -0.059764"/>
      <geometry>
        <mesh filename="file:///home/ubuntu/ethr_rc_robot_assets/humanoid-description/humanoid_final_copy_description/meshes/elbow_lower_right_1.stl" scale="0.001 0.001 0.001"/>
      </geometry>
    </collision>
  </link>
  <link name="motor_5_right_1">
    <inertial>
      <origin rpy="0 0 0" xyz="-0.03363447229579386 0.0003556677422903859 -0.025518962950758478"/>
      <mass value="0.570"/>
      <inertia ixx="0.000655" ixy="-5e-06" ixz="-5e-06" iyy="0.000651" iyz="-2.1e-05" izz="0.00063"/>
    </inertial>
    <visual>
      <origin rpy="0 0 0" xyz="0.25945 0.098031 -0.014254"/>
      <geometry>
        <mesh filename="file:///home/ubuntu/ethr_rc_robot_assets/humanoid-description/humanoid_final_copy_description/meshes/motor_5_right_1.stl" scale="0.001 0.001 0.001"/>
      </geometry>
      <material name="silver"/>
    </visual>
    <collision>
      <origin rpy="0 0 0" xyz="0.25945 0.098031 -0.014254"/>
      <geometry>
        <mesh filename="file:///home/ubuntu/ethr_rc_robot_assets/humanoid-description/humanoid_final_copy_description/meshes/motor_5_right_1.stl" scale="0.001 0.001 0.001"/>
      </geometry>
    </collision>
  </link>
  <link name="wrist_upper_right_1">
    <inertial>
      <origin rpy="0 0 0" xyz="-0.002711957553959643 -0.0027794346498556805 -0.012823790027361948"/>
      <mass value="0.031126167143252212"/>
      <inertia ixx="2.2e-05" ixy="1e-06" ixz="-1e-06" iyy="2.4e-05" iyz="3e-06" izz="2e-05"/>
    </inertial>
    <visual>
      <origin rpy="0 0 0" xyz="0.299008 0.113647 0.03807"/>
      <geometry>
        <mesh filename="file:///home/ubuntu/ethr_rc_robot_assets/humanoid-description/humanoid_final_copy_description/meshes/wrist_upper_right_1.stl" scale="0.001 0.001 0.001"/>
      </geometry>
      <material name="silver"/>
    </visual>
    <collision>
      <origin rpy="0 0 0" xyz="0.299008 0.113647 0.03807"/>
      <geometry>
        <mesh filename="file:///home/ubuntu/ethr_rc_robot_assets/humanoid-description/humanoid_final_copy_description/meshes/wrist_upper_right_1.stl" scale="0.001 0.001 0.001"/>
      </geometry>
    </collision>
  </link>
  <link name="motor_6_right_1">
    <inertial>
      <origin rpy="0 0 0" xyz="-0.0033966918987262673 -0.039907456152230125 -0.013381675981556186"/>
      <mass value="0.570"/>
      <inertia ixx="0.000656" ixy="4e-06" ixz="0.0" iyy="0.000627" iyz="2e-05" izz="0.000653"/>
    </inertial>
    <visual>
      <origin rpy="0 0 0" xyz="0.3034 0.098216 0.059827"/>
      <geometry>
        <mesh filename="file:///home/ubuntu/ethr_rc_robot_assets/humanoid-description/humanoid_final_copy_description/meshes/motor_6_right_1.stl" scale="0.001 0.001 0.001"/>
      </geometry>
      <material name="silver"/>
    </visual>
    <collision>
      <origin rpy="0 0 0" xyz="0.3034 0.098216 0.059827"/>
      <geometry>
        <mesh filename="file:///home/ubuntu/ethr_rc_robot_assets/humanoid-description/humanoid_final_copy_description/meshes/motor_6_right_1.stl" scale="0.001 0.001 0.001"/>
      </geometry>
    </collision>
  </link>
  <link name="wrist_lower_right_1">
    <inertial>
      <origin rpy="0 0 0" xyz="-0.005887266738570207 -0.021577367607174353 -0.0473346080681072"/>
      <mass value="0.0510848552599698"/>
      <inertia ixx="7.1e-05" ixy="-6e-06" ixz="-6e-06" iyy="7.1e-05" iyz="-1.8e-05" izz="3.3e-05"/>
    </inertial>
    <visual>
      <origin rpy="0 0 0" xyz="0.303781 0.165604 0.057576"/>
      <geometry>
        <mesh filename="file:///home/ubuntu/ethr_rc_robot_assets/humanoid-description/humanoid_final_copy_description/meshes/wrist_lower_right_1.stl" scale="0.001 0.001 0.001"/>
      </geometry>
      <material name="silver"/>
    </visual>
    <collision>
      <origin rpy="0 0 0" xyz="0.303781 0.165604 0.057576"/>
      <geometry>
        <mesh filename="file:///home/ubuntu/ethr_rc_robot_assets/humanoid-description/humanoid_final_copy_description/meshes/wrist_lower_right_1.stl" scale="0.001 0.001 0.001"/>
      </geometry>
    </collision>
  </link>
  <link name="motor_7_right_1">
    <inertial>
      <origin rpy="0 0 0" xyz="-0.02736729764523943 -0.03172774863281813 0.005855823587693432"/>
      <mass value="0.570"/>
      <inertia ixx="0.000618" ixy="2e-06" ixz="1.1e-05" iyy="0.000657" iyz="3e-06" izz="0.00066"/>
    </inertial>
    <visual>
      <origin rpy="0 0 0" xyz="0.294907 0.140765 0.142689"/>
      <geometry>
        <mesh filename="file:///home/ubuntu/ethr_rc_robot_assets/humanoid-description/humanoid_final_copy_description/meshes/motor_7_right_1.stl" scale="0.001 0.001 0.001"/>
      </geometry>
      <material name="silver"/>
    </visual>
    <collision>
      <origin rpy="0 0 0" xyz="0.294907 0.140765 0.142689"/>
      <geometry>
        <mesh filename="file:///home/ubuntu/ethr_rc_robot_assets/humanoid-description/humanoid_final_copy_description/meshes/motor_7_right_1.stl" scale="0.001 0.001 0.001"/>
      </geometry>
    </collision>
  </link>
  <link name="eef_right_1">
    <inertial>
      <origin rpy="0 0 0" xyz="0.011042620207134313 -0.03434694543701433 -0.06227719391707298"/>
      <mass value="0.3310421876503466"/>
      <inertia ixx="0.000221" ixy="1.6e-05" ixz="3e-05" iyy="0.000207" iyz="-4.2e-05" izz="0.00015"/>
    </inertial>
    <visual>
      <origin rpy="0 0 0" xyz="0.353348 0.172025 0.130286"/>
      <geometry>
        <mesh filename="file:///home/ubuntu/ethr_rc_robot_assets/humanoid-description/humanoid_final_copy_description/meshes/eef_right_1.stl" scale="0.001 0.001 0.001"/>
      </geometry>
      <material name="silver"/>
    </visual>
    <collision>
      <origin rpy="0 0 0" xyz="0.353348 0.172025 0.130286"/>
      <geometry>
        <mesh filename="file:///home/ubuntu/ethr_rc_robot_assets/humanoid-description/humanoid_final_copy_description/meshes/eef_right_1.stl" scale="0.001 0.001 0.001"/>
      </geometry>
    </collision>
  </link>
  <link name="motor_1_right_1">
    <inertial>
      <origin rpy="0 0 0" xyz="0.020581197114426658 -0.040962302223338645 -0.003549543416310197"/>
      <mass value="1.05"/>
      <inertia ixx="0.001972" ixy="7.4e-05" ixz="-1.7e-05" iyy="0.001994" iyz="3.8e-05" izz="0.00207"/>
    </inertial>
    <visual>
      <origin rpy="0 0 0" xyz="0.173947 -0.09865 -0.225664"/>
      <geometry>
        <mesh filename="file:///home/ubuntu/ethr_rc_robot_assets/humanoid-description/humanoid_final_copy_description/meshes/motor_1_right_1.stl" scale="0.001 0.001 0.001"/>
      </geometry>
      <material name="silver"/>
    </visual>
    <collision>
      <origin rpy="0 0 0" xyz="0.173947 -0.09865 -0.225664"/>
      <geometry>
        <mesh filename="file:///home/ubuntu/ethr_rc_robot_assets/humanoid-description/humanoid_final_copy_description/meshes/motor_1_right_1.stl" scale="0.001 0.001 0.001"/>
      </geometry>
    </collision>
  </link>
  <link name="motor_1_left_1">
    <inertial>
      <origin rpy="0 0 0" xyz="-0.021519057907961575 -0.04047142850779704 -0.0036164192771802606"/>
      <mass value="1.05"/>
      <inertia ixx="0.001968" ixy="-7.3e-05" ixz="1.8e-05" iyy="0.001998" iyz="3.7e-05" izz="0.002071"/>
    </inertial>
    <visual>
      <origin rpy="0 0 0" xyz="-0.182799 -0.094491 -0.226237"/>
      <geometry>
        <mesh filename="file:///home/ubuntu/ethr_rc_robot_assets/humanoid-description/humanoid_final_copy_description/meshes/motor_1_left_1.stl" scale="0.001 0.001 0.001"/>
      </geometry>
      <material name="silver"/>
    </visual>
    <collision>
      <origin rpy="0 0 0" xyz="-0.182799 -0.094491 -0.226237"/>
      <geometry>
        <mesh filename="file:///home/ubuntu/ethr_rc_robot_assets/humanoid-description/humanoid_final_copy_description/meshes/motor_1_left_1.stl" scale="0.001 0.001 0.001"/>
      </geometry>
    </collision>
  </link>
  <link name="rotor_waist_1">
    <inertial>
      <origin rpy="0 0 0" xyz="6.903568608212802e-05 -0.0008416904562534369 -0.045800304788548074"/>
      <mass value="1.96"/>
      <inertia ixx="0.005253" ixy="0.0" ixz="1e-06" iyy="0.005212" iyz="-6e-05" izz="0.005212"/>
    </inertial>
    <visual>
      <origin rpy="0 0 0" xyz="-0.004471 -0.043019 0.190181"/>
      <geometry>
        <mesh filename="file:///home/ubuntu/ethr_rc_robot_assets/humanoid-description/humanoid_final_copy_description/meshes/rotor_waist_1.stl" scale="0.001 0.001 0.001"/>
      </geometry>
      <material name="silver"/>
    </visual>
    <collision>
      <origin rpy="0 0 0" xyz="-0.004471 -0.043019 0.190181"/>
      <geometry>
        <mesh filename="file:///home/ubuntu/ethr_rc_robot_assets/humanoid-description/humanoid_final_copy_description/meshes/rotor_waist_1.stl" scale="0.001 0.001 0.001"/>
      </geometry>
    </collision>
  </link>
  <link name="Middle_Connector_Platre_1">
    <inertial>
      <origin rpy="0 0 0" xyz="0.00015987518520738965 0.011492165258866503 -0.0080464693554467"/>
      <mass value="0.6319600175244401"/>
      <inertia ixx="0.001306" ixy="-8e-06" ixz="-1e-06" iyy="0.000601" iyz="6e-06" izz="0.001807"/>
    </inertial>
    <visual>
      <origin rpy="0 0 0" xyz="-0.004487 -0.04297 0.200231"/>
      <geometry>
        <mesh filename="file:///home/ubuntu/ethr_rc_robot_assets/humanoid-description/humanoid_final_copy_description/meshes/Middle_Connector_Platre_1.stl" scale="0.001 0.001 0.001"/>
      </geometry>
      <material name="silver"/>
    </visual>
    <collision>
      <origin rpy="0 0 0" xyz="-0.004487 -0.04297 0.200231"/>
      <geometry>
        <mesh filename="file:///home/ubuntu/ethr_rc_robot_assets/humanoid-description/humanoid_final_copy_description/meshes/Middle_Connector_Platre_1.stl" scale="0.001 0.001 0.001"/>
      </geometry>
    </collision>
  </link>
  <link name="abductor_central_1">
    <inertial>
      <origin rpy="0 0 0" xyz="0.0005480910294215812 0.04600909155839286 -0.0012696523637903412"/>
      <mass value="1.96"/>
      <inertia ixx="0.005387" ixy="-1e-06" ixz="4e-06" iyy="0.005399" iyz="0.000105" izz="0.005286"/>
    </inertial>
    <visual>
      <origin rpy="0 0 0" xyz="-0.005289 -0.107768 0.20856"/>
      <geometry>
        <mesh filename="file:///home/ubuntu/ethr_rc_robot_assets/humanoid-description/humanoid_final_copy_description/meshes/abductor_central_1.stl" scale="0.001 0.001 0.001"/>
      </geometry>
      <material name="silver"/>
    </visual>
    <collision>
      <origin rpy="0 0 0" xyz="-0.005289 -0.107768 0.20856"/>
      <geometry>
        <mesh filename="file:///home/ubuntu/ethr_rc_robot_assets/humanoid-description/humanoid_final_copy_description/meshes/abductor_central_1.stl" scale="0.001 0.001 0.001"/>
      </geometry>
    </collision>
  </link>
  <link name="hip_subframe_1">
    <inertial>
      <origin rpy="0 0 0" xyz="-0.001040461852483741 -0.09890103793087081 -0.06218344493617631"/>
      <mass value="2.170239101637896"/>
      <inertia ixx="0.033021" ixy="0.000564" ixz="-0.000151" iyy="0.08117" iyz="-0.005193" izz="0.085835"/>
    </inertial>
    <visual>
      <origin rpy="0 0 0" xyz="-0.005564 -0.131316 0.208676"/>
      <geometry>
        <mesh filename="file:///home/ubuntu/ethr_rc_robot_assets/humanoid-description/humanoid_final_copy_description/meshes/hip_subframe_1.stl" scale="0.001 0.001 0.001"/>
      </geometry>
      <material name="silver"/>
    </visual>
    <collision>
      <origin rpy="0 0 0" xyz="-0.005564 -0.131316 0.208676"/>
      <geometry>
        <mesh filename="file:///home/ubuntu/ethr_rc_robot_assets/humanoid-description/humanoid_final_copy_description/meshes/hip_subframe_1.stl" scale="0.001 0.001 0.001"/>
      </geometry>
    </collision>
  </link>
  <link name="flexor_right_1">
    <inertial>
      <origin rpy="0 0 0" xyz="-0.28854704364837624 0.028536127808607085 0.2836095771641781"/>
      <mass value="1.96"/>
      <inertia ixx="0.005181" ixy="-0.0" ixz="5.2e-05" iyy="0.005253" iyz="-0.0" izz="0.005243"/>
    </inertial>
    <visual>
      <origin rpy="0 0 0" xyz="-0.157121 0.004985 0.5722"/>
      <geometry>
        <mesh filename="file:///home/ubuntu/ethr_rc_robot_assets/humanoid-description/humanoid_final_copy_description/meshes/flexor_right_1.stl" scale="0.001 0.001 0.001"/>
      </geometry>
      <material name="silver"/>
    </visual>
    <collision>
      <origin rpy="0 0 0" xyz="-0.157121 0.004985 0.5722"/>
      <geometry>
        <mesh filename="file:///home/ubuntu/ethr_rc_robot_assets/humanoid-description/humanoid_final_copy_description/meshes/flexor_right_1.stl" scale="0.001 0.001 0.001"/>
      </geometry>
    </collision>
  </link>
  <link name="flexor_left_1">
    <inertial>
      <origin rpy="0 0 0" xyz="0.2970397405179065 0.018045808091662105 0.2840637453879699"/>
      <mass value="1.96"/>
      <inertia ixx="0.005181" ixy="2e-06" ixz="-5.2e-05" iyy="0.005253" iyz="1e-06" izz="0.005243"/>
    </inertial>
    <visual>
      <origin rpy="0 0 0" xyz="0.156773 -0.002338 0.572209"/>
      <geometry>
        <mesh filename="file:///home/ubuntu/ethr_rc_robot_assets/humanoid-description/humanoid_final_copy_description/meshes/flexor_left_1.stl" scale="0.001 0.001 0.001"/>
      </geometry>
      <material name="silver"/>
    </visual>
    <collision>
      <origin rpy="0 0 0" xyz="0.156773 -0.002338 0.572209"/>
      <geometry>
        <mesh filename="file:///home/ubuntu/ethr_rc_robot_assets/humanoid-description/humanoid_final_copy_description/meshes/flexor_left_1.stl" scale="0.001 0.001 0.001"/>
      </geometry>
    </collision>
  </link>
  <link name="flexor_plate_left_1">
    <inertial>
      <origin rpy="0 0 0" xyz="-0.0142618954945119 0.05255797156467319 -0.011904784809336821"/>
      <mass value="0.5850574919541455"/>
      <inertia ixx="0.001827" ixy="0.000556" ixz="-0.000134" iyy="0.00123" iyz="0.000122" izz="0.002074"/>
    </inertial>
    <visual>
      <origin rpy="0 0 0" xyz="-0.185609 -0.019793 0.299577"/>
      <geometry>
        <mesh filename="file:///home/ubuntu/ethr_rc_robot_assets/humanoid-description/humanoid_final_copy_description/meshes/flexor_plate_left_1.stl" scale="0.001 0.001 0.001"/>
      </geometry>
      <material name="silver"/>
    </visual>
    <collision>
      <origin rpy="0 0 0" xyz="-0.185609 -0.019793 0.299577"/>
      <geometry>
        <mesh filename="file:///home/ubuntu/ethr_rc_robot_assets/humanoid-description/humanoid_final_copy_description/meshes/flexor_plate_left_1.stl" scale="0.001 0.001 0.001"/>
      </geometry>
    </collision>
  </link>
  <link name="flexor_plate_right_1">
    <inertial>
      <origin rpy="0 0 0" xyz="0.015530625698542383 0.052101715147010216 -0.011891258148412187"/>
      <mass value="0.5850574919541748"/>
      <inertia ixx="0.001793" ixy="-0.000566" ixz="0.000137" iyy="0.001257" iyz="0.000117" izz="0.002069"/>
    </inertial>
    <visual>
      <origin rpy="0 0 0" xyz="0.176732 -0.024018 0.300171"/>
      <geometry>
        <mesh filename="file:///home/ubuntu/ethr_rc_robot_assets/humanoid-description/humanoid_final_copy_description/meshes/flexor_plate_right_1.stl" scale="0.001 0.001 0.001"/>
      </geometry>
      <material name="silver"/>
    </visual>
    <collision>
      <origin rpy="0 0 0" xyz="0.176732 -0.024018 0.300171"/>
      <geometry>
        <mesh filename="file:///home/ubuntu/ethr_rc_robot_assets/humanoid-description/humanoid_final_copy_description/meshes/flexor_plate_right_1.stl" scale="0.001 0.001 0.001"/>
      </geometry>
    </collision>
  </link>
  <link name="abductor_right_1">
    <inertial>
      <origin rpy="0 0 0" xyz="0.0006234018653276802 0.04400245679649717 -0.013498906240339503"/>
      <mass value="1.96"/>
      <inertia ixx="0.005387" ixy="1e-06" ixz="-2e-06" iyy="0.005445" iyz="6.1e-05" izz="0.00524"/>
    </inertial>
    <visual>
      <origin rpy="0 0 0" xyz="0.120682 -0.111738 0.315326"/>
      <geometry>
        <mesh filename="file:///home/ubuntu/ethr_rc_robot_assets/humanoid-description/humanoid_final_copy_description/meshes/abductor_right_1.stl" scale="0.001 0.001 0.001"/>
      </geometry>
      <material name="silver"/>
    </visual>
    <collision>
      <origin rpy="0 0 0" xyz="0.120682 -0.111738 0.315326"/>
      <geometry>
        <mesh filename="file:///home/ubuntu/ethr_rc_robot_assets/humanoid-description/humanoid_final_copy_description/meshes/abductor_right_1.stl" scale="0.001 0.001 0.001"/>
      </geometry>
    </collision>
  </link>
  <link name="abductor_left_1">
    <inertial>
      <origin rpy="0 0 0" xyz="0.0005200581214259425 0.044084963479401884 -0.013229352748698298"/>
      <mass value="1.96"/>
      <inertia ixx="0.005387" ixy="-0.0" ixz="4e-06" iyy="0.005444" iyz="6.2e-05" izz="0.005241"/>
    </inertial>
    <visual>
      <origin rpy="0 0 0" xyz="-0.131706 -0.109099 0.314789"/>
      <geometry>
        <mesh filename="file:///home/ubuntu/ethr_rc_robot_assets/humanoid-description/humanoid_final_copy_description/meshes/abductor_left_1.stl" scale="0.001 0.001 0.001"/>
      </geometry>
      <material name="silver"/>
    </visual>
    <collision>
      <origin rpy="0 0 0" xyz="-0.131706 -0.109099 0.314789"/>
      <geometry>
        <mesh filename="file:///home/ubuntu/ethr_rc_robot_assets/humanoid-description/humanoid_final_copy_description/meshes/abductor_left_1.stl" scale="0.001 0.001 0.001"/>
      </geometry>
    </collision>
  </link>
  <link name="femural_head_left_1">
    <inertial>
      <origin rpy="0 0 0" xyz="0.2591493729789929 0.18980052410277798 0.18130281748646637"/>
      <mass value="1.5"/>
      <inertia ixx="0.018593" ixy="3.6e-05" ixz="-2.3e-05" iyy="0.015985" iyz="-0.006838" izz="0.015048"/>
    </inertial>
    <visual>
      <origin rpy="0 0 0" xyz="0.127241 0.106001 0.600857"/>
      <geometry>
        <mesh filename="file:///home/ubuntu/ethr_rc_robot_assets/humanoid-description/humanoid_final_copy_description/meshes/femural_head_left_1.stl" scale="0.001 0.001 0.001"/>
      </geometry>
      <material name="silver"/>
    </visual>
    <collision>
      <origin rpy="0 0 0" xyz="0.127241 0.106001 0.600857"/>
      <geometry>
        <mesh filename="file:///home/ubuntu/ethr_rc_robot_assets/humanoid-description/humanoid_final_copy_description/meshes/femural_head_left_1.stl" scale="0.001 0.001 0.001"/>
      </geometry>
    </collision>
  </link>
  <link name="femural_head_right_1">
    <inertial>
      <origin rpy="0 0 0" xyz="-0.2428211243982835 0.199750114661938 0.17984275362516505"/>
      <mass value="1.5"/>
      <inertia ixx="0.018593" ixy="2.8e-05" ixz="-4.2e-05" iyy="0.015901" iyz="-0.006843" izz="0.015131"/>
    </inertial>
    <visual>
      <origin rpy="0 0 0" xyz="-0.122274 0.113951 0.599778"/>
      <geometry>
        <mesh filename="file:///home/ubuntu/ethr_rc_robot_assets/humanoid-description/humanoid_final_copy_description/meshes/femural_head_right_1.stl" scale="0.001 0.001 0.001"/>
      </geometry>
      <material name="silver"/>
    </visual>
    <collision>
      <origin rpy="0 0 0" xyz="-0.122274 0.113951 0.599778"/>
      <geometry>
        <mesh filename="file:///home/ubuntu/ethr_rc_robot_assets/humanoid-description/humanoid_final_copy_description/meshes/femural_head_right_1.stl" scale="0.001 0.001 0.001"/>
      </geometry>
    </collision>
  </link>
  <link name="rotor_right_1">
    <inertial>
      <origin rpy="0 0 0" xyz="-0.24993256746772563 0.02882545875464209 0.3008465695860785"/>
      <mass value="1.96"/>
      <inertia ixx="0.005253" ixy="0.0" ixz="-0.0" iyy="0.005213" iyz="6e-05" izz="0.005211"/>
    </inertial>
    <visual>
      <origin rpy="0 0 0" xyz="-0.126651 0.005281 0.750282"/>
      <geometry>
        <mesh filename="file:///home/ubuntu/ethr_rc_robot_assets/humanoid-description/humanoid_final_copy_description/meshes/rotor_right_1.stl" scale="0.001 0.001 0.001"/>
      </geometry>
      <material name="silver"/>
    </visual>
    <collision>
      <origin rpy="0 0 0" xyz="-0.126651 0.005281 0.750282"/>
      <geometry>
        <mesh filename="file:///home/ubuntu/ethr_rc_robot_assets/humanoid-description/humanoid_final_copy_description/meshes/rotor_right_1.stl" scale="0.001 0.001 0.001"/>
      </geometry>
    </collision>
  </link>
  <link name="rotor_left_1">
    <inertial>
      <origin rpy="0 0 0" xyz="0.25225577275981437 0.019045035564066747 0.30192197467773885"/>
      <mass value="1.96"/>
      <inertia ixx="0.005253" ixy="-1e-06" ixz="2e-06" iyy="0.005213" iyz="6e-05" izz="0.005211"/>
    </inertial>
    <visual>
      <origin rpy="0 0 0" xyz="0.122923 -0.002674 0.751356"/>
      <geometry>
        <mesh filename="file:///home/ubuntu/ethr_rc_robot_assets/humanoid-description/humanoid_final_copy_description/meshes/rotor_left_1.stl" scale="0.001 0.001 0.001"/>
      </geometry>
      <material name="silver"/>
    </visual>
    <collision>
      <origin rpy="0 0 0" xyz="0.122923 -0.002674 0.751356"/>
      <geometry>
        <mesh filename="file:///home/ubuntu/ethr_rc_robot_assets/humanoid-description/humanoid_final_copy_description/meshes/rotor_left_1.stl" scale="0.001 0.001 0.001"/>
      </geometry>
    </collision>
  </link>
  <link name="femur_left_1">
    <inertial>
      <origin rpy="0 0 0" xyz="0.008647020835322206 0.00013028585323252018 -0.20691330179992673"/>
      <mass value="0.8123849547337765"/>
      <inertia ixx="0.011954" ixy="-1e-06" ixz="0.000855" iyy="0.01186" iyz="-0.0" izz="0.000648"/>
    </inertial>
    <visual>
      <origin rpy="0 0 0" xyz="-0.129417 -0.022411 0.495236"/>
      <geometry>
        <mesh filename="file:///home/ubuntu/ethr_rc_robot_assets/humanoid-description/humanoid_final_copy_description/meshes/femur_left_1.stl" scale="0.001 0.001 0.001"/>
      </geometry>
      <material name="silver"/>
    </visual>
    <collision>
      <origin rpy="0 0 0" xyz="-0.129417 -0.022411 0.495236"/>
      <geometry>
        <mesh filename="file:///home/ubuntu/ethr_rc_robot_assets/humanoid-description/humanoid_final_copy_description/meshes/femur_left_1.stl" scale="0.001 0.001 0.001"/>
      </geometry>
    </collision>
  </link>
  <link name="femur_right_1">
    <inertial>
      <origin rpy="0 0 0" xyz="0.008651616880114663 -0.001121178020522924 -0.20690992299721117"/>
      <mass value="0.8123849547337765"/>
      <inertia ixx="0.011954" ixy="5e-06" ixz="0.000856" iyy="0.011859" iyz="-6.8e-05" izz="0.000649"/>
    </inertial>
    <visual>
      <origin rpy="0 0 0" xyz="0.123207 -0.023956 0.495241"/>
      <geometry>
        <mesh filename="file:///home/ubuntu/ethr_rc_robot_assets/humanoid-description/humanoid_final_copy_description/meshes/femur_right_1.stl" scale="0.001 0.001 0.001"/>
      </geometry>
      <material name="silver"/>
    </visual>
    <collision>
      <origin rpy="0 0 0" xyz="0.123207 -0.023956 0.495241"/>
      <geometry>
        <mesh filename="file:///home/ubuntu/ethr_rc_robot_assets/humanoid-description/humanoid_final_copy_description/meshes/femur_right_1.stl" scale="0.001 0.001 0.001"/>
      </geometry>
    </collision>
  </link>
  <link name="knee_right_1">
    <inertial>
      <origin rpy="0 0 0" xyz="-0.023925641142481163 0.0002841731338361353 -0.0010822543799660078"/>
      <mass value="1.96"/>
      <inertia ixx="0.005398" ixy="1e-06" ixz="-0.000105" iyy="0.005387" iyz="3e-06" izz="0.005287"/>
    </inertial>
    <visual>
      <origin rpy="0 0 0" xyz="0.089181 -0.02195 0.857718"/>
      <geometry>
        <mesh filename="file:///home/ubuntu/ethr_rc_robot_assets/humanoid-description/humanoid_final_copy_description/meshes/knee_right_1.stl" scale="0.001 0.001 0.001"/>
      </geometry>
      <material name="silver"/>
    </visual>
    <collision>
      <origin rpy="0 0 0" xyz="0.089181 -0.02195 0.857718"/>
      <geometry>
        <mesh filename="file:///home/ubuntu/ethr_rc_robot_assets/humanoid-description/humanoid_final_copy_description/meshes/knee_right_1.stl" scale="0.001 0.001 0.001"/>
      </geometry>
    </collision>
  </link>
  <link name="knee_left_1">
    <inertial>
      <origin rpy="0 0 0" xyz="-0.02392490306531922 0.0003262566410805849 -0.0010794071770737768"/>
      <mass value="1.96"/>
      <inertia ixx="0.005398" ixy="1e-06" ixz="-0.000105" iyy="0.005387" iyz="4e-06" izz="0.005287"/>
    </inertial>
    <visual>
      <origin rpy="0 0 0" xyz="-0.163435 -0.02257 0.85772"/>
      <geometry>
        <mesh filename="file:///home/ubuntu/ethr_rc_robot_assets/humanoid-description/humanoid_final_copy_description/meshes/knee_left_1.stl" scale="0.001 0.001 0.001"/>
      </geometry>
      <material name="silver"/>
    </visual>
    <collision>
      <origin rpy="0 0 0" xyz="-0.163435 -0.02257 0.85772"/>
      <geometry>
        <mesh filename="file:///home/ubuntu/ethr_rc_robot_assets/humanoid-description/humanoid_final_copy_description/meshes/knee_left_1.stl" scale="0.001 0.001 0.001"/>
      </geometry>
    </collision>
  </link>
  <link name="ankle_actuator_upper_right_1">
    <inertial>
      <origin rpy="0 0 0" xyz="-0.0003041180597410098 -0.02110716409337814 0.00011418024886600264"/>
      <mass value="0.9038344202380671"/>
      <inertia ixx="0.000901" ixy="2e-06" ixz="-1e-06" iyy="0.001198" iyz="-7e-06" izz="0.000876"/>
    </inertial>
    <visual>
      <origin rpy="0 0 0" xyz="0.113281 -0.044247 1.079886"/>
      <geometry>
        <mesh filename="file:///home/ubuntu/ethr_rc_robot_assets/humanoid-description/humanoid_final_copy_description/meshes/ankle_actuator_upper_right_1.stl" scale="0.001 0.001 0.001"/>
      </geometry>
      <material name="silver"/>
    </visual>
    <collision>
      <origin rpy="0 0 0" xyz="0.113281 -0.044247 1.079886"/>
      <geometry>
        <mesh filename="file:///home/ubuntu/ethr_rc_robot_assets/humanoid-description/humanoid_final_copy_description/meshes/ankle_actuator_upper_right_1.stl" scale="0.001 0.001 0.001"/>
      </geometry>
    </collision>
  </link>
  <link name="ankle_actuator_lower_right_1">
    <inertial>
      <origin rpy="0 0 0" xyz="-0.0003048759533671175 -0.021107455031487823 0.00011406565669513924"/>
      <mass value="0.9038344202380688"/>
      <inertia ixx="0.000901" ixy="2e-06" ixz="-1e-06" iyy="0.001198" iyz="-7e-06" izz="0.000876"/>
    </inertial>
    <visual>
      <origin rpy="0 0 0" xyz="0.113436 -0.044693 0.979887"/>
      <geometry>
        <mesh filename="file:///home/ubuntu/ethr_rc_robot_assets/humanoid-description/humanoid_final_copy_description/meshes/ankle_actuator_lower_right_1.stl" scale="0.001 0.001 0.001"/>
      </geometry>
      <material name="silver"/>
    </visual>
    <collision>
      <origin rpy="0 0 0" xyz="0.113436 -0.044693 0.979887"/>
      <geometry>
        <mesh filename="file:///home/ubuntu/ethr_rc_robot_assets/humanoid-description/humanoid_final_copy_description/meshes/ankle_actuator_lower_right_1.stl" scale="0.001 0.001 0.001"/>
      </geometry>
    </collision>
  </link>
  <link name="ankle_actuator_upper_left_1">
    <inertial>
      <origin rpy="0 0 0" xyz="-0.00033644995275386447 -0.02110677840467828 -1.5550255457963402e-05"/>
      <mass value="0.9038344202380688"/>
      <inertia ixx="0.000901" ixy="3e-06" ixz="-1e-06" iyy="0.001198" iyz="-5e-06" izz="0.000876"/>
    </inertial>
    <visual>
      <origin rpy="0 0 0" xyz="-0.139213 -0.046095 0.979746"/>
      <geometry>
        <mesh filename="file:///home/ubuntu/ethr_rc_robot_assets/humanoid-description/humanoid_final_copy_description/meshes/ankle_actuator_upper_left_1.stl" scale="0.001 0.001 0.001"/>
      </geometry>
      <material name="silver"/>
    </visual>
    <collision>
      <origin rpy="0 0 0" xyz="-0.139213 -0.046095 0.979746"/>
      <geometry>
        <mesh filename="file:///home/ubuntu/ethr_rc_robot_assets/humanoid-description/humanoid_final_copy_description/meshes/ankle_actuator_upper_left_1.stl" scale="0.001 0.001 0.001"/>
      </geometry>
    </collision>
  </link>
  <link name="ankle_actuator_lower_left_1">
    <inertial>
      <origin rpy="0 0 0" xyz="-0.0003364871389758828 -0.021107292789431183 -1.5294804431631448e-05"/>
      <mass value="0.9038344202380671"/>
      <inertia ixx="0.000901" ixy="3e-06" ixz="-1e-06" iyy="0.001198" iyz="-5e-06" izz="0.000876"/>
    </inertial>
    <visual>
      <origin rpy="0 0 0" xyz="-0.139367 -0.046261 1.079746"/>
      <geometry>
        <mesh filename="file:///home/ubuntu/ethr_rc_robot_assets/humanoid-description/humanoid_final_copy_description/meshes/ankle_actuator_lower_left_1.stl" scale="0.001 0.001 0.001"/>
      </geometry>
      <material name="silver"/>
    </visual>
    <collision>
      <origin rpy="0 0 0" xyz="-0.139367 -0.046261 1.079746"/>
      <geometry>
        <mesh filename="file:///home/ubuntu/ethr_rc_robot_assets/humanoid-description/humanoid_final_copy_description/meshes/ankle_actuator_lower_left_1.stl" scale="0.001 0.001 0.001"/>
      </geometry>
    </collision>
  </link>
  <link name="tibia_subframe_left_1">
    <inertial>
      <origin rpy="0 0 0" xyz="-0.0328436483638305 0.00306434221932873 -0.17220718956099645"/>
      <mass value="0.5778017399697978"/>
      <inertia ixx="0.007171" ixy="1.9e-05" ixz="-0.001138" iyy="0.007447" iyz="0.000119" izz="0.000719"/>
    </inertial>
    <visual>
      <origin rpy="0 0 0" xyz="-0.18648 -0.022266 0.857685"/>
      <geometry>
        <mesh filename="file:///home/ubuntu/ethr_rc_robot_assets/humanoid-description/humanoid_final_copy_description/meshes/tibia_subframe_left_1.stl" scale="0.001 0.001 0.001"/>
      </geometry>
      <material name="silver"/>
    </visual>
    <collision>
      <origin rpy="0 0 0" xyz="-0.18648 -0.022266 0.857685"/>
      <geometry>
        <mesh filename="file:///home/ubuntu/ethr_rc_robot_assets/humanoid-description/humanoid_final_copy_description/meshes/tibia_subframe_left_1.stl" scale="0.001 0.001 0.001"/>
      </geometry>
    </collision>
  </link>
  <link name="tibia_subframe_right_1">
    <inertial>
      <origin rpy="0 0 0" xyz="-0.032844583092889776 0.001961464227493954 -0.17222356294920826"/>
      <mass value="0.5778017399697978"/>
      <inertia ixx="0.007171" ixy="1.2e-05" ixz="-0.001138" iyy="0.007448" iyz="7.6e-05" izz="0.000718"/>
    </inertial>
    <visual>
      <origin rpy="0 0 0" xyz="0.066136 -0.021682 0.857681"/>
      <geometry>
        <mesh filename="file:///home/ubuntu/ethr_rc_robot_assets/humanoid-description/humanoid_final_copy_description/meshes/tibia_subframe_right_1.stl" scale="0.001 0.001 0.001"/>
      </geometry>
      <material name="silver"/>
    </visual>
    <collision>
      <origin rpy="0 0 0" xyz="0.066136 -0.021682 0.857681"/>
      <geometry>
        <mesh filename="file:///home/ubuntu/ethr_rc_robot_assets/humanoid-description/humanoid_final_copy_description/meshes/tibia_subframe_right_1.stl" scale="0.001 0.001 0.001"/>
      </geometry>
    </collision>
  </link>
  <link name="ankle_spherical_joint_left_1">
    <inertial>
      <origin rpy="0 0 0" xyz="0.00018773923365764111 0.01424920401966162 2.3913256613772305e-05"/>
      <mass value="0.19692191115135207"/>
      <inertia ixx="2.6e-05" ixy="-0.0" ixz="0.0" iyy="2.6e-05" iyz="-0.0" izz="3.3e-05"/>
    </inertial>
    <visual>
      <origin rpy="0 0 0" xyz="-0.139053 -0.012404 1.164803"/>
      <geometry>
        <mesh filename="file:///home/ubuntu/ethr_rc_robot_assets/humanoid-description/humanoid_final_copy_description/meshes/ankle_spherical_joint_left_1.stl" scale="0.001 0.001 0.001"/>
      </geometry>
      <material name="silver"/>
    </visual>
    <collision>
      <origin rpy="0 0 0" xyz="-0.139053 -0.012404 1.164803"/>
      <geometry>
        <mesh filename="file:///home/ubuntu/ethr_rc_robot_assets/humanoid-description/humanoid_final_copy_description/meshes/ankle_spherical_joint_left_1.stl" scale="0.001 0.001 0.001"/>
      </geometry>
    </collision>
  </link>
  <link name="ankle_spherical_joint_right_1">
    <inertial>
      <origin rpy="0 0 0" xyz="-0.00016642003909271563 -0.014249199834368658 6.281151238440863e-05"/>
      <mass value="0.19692191115135207"/>
      <inertia ixx="2.6e-05" ixy="0.0" ixz="0.0" iyy="2.6e-05" iyz="0.0" izz="3.3e-05"/>
    </inertial>
    <visual>
      <origin rpy="0 0 0" xyz="0.113209 -0.038369 1.16486"/>
      <geometry>
        <mesh filename="file:///home/ubuntu/ethr_rc_robot_assets/humanoid-description/humanoid_final_copy_description/meshes/ankle_spherical_joint_right_1.stl" scale="0.001 0.001 0.001"/>
      </geometry>
      <material name="silver"/>
    </visual>
    <collision>
      <origin rpy="0 0 0" xyz="0.113209 -0.038369 1.16486"/>
      <geometry>
        <mesh filename="file:///home/ubuntu/ethr_rc_robot_assets/humanoid-description/humanoid_final_copy_description/meshes/ankle_spherical_joint_right_1.stl" scale="0.001 0.001 0.001"/>
      </geometry>
    </collision>
  </link>
  <link name="foot_right_1">
    <inertial>
      <origin rpy="0 0 0" xyz="-0.014457574642628312 -0.01349159726128919 -0.03958389282193675"/>
      <mass value="0.5416388803238992"/>
      <inertia ixx="0.001546" ixy="-1.4e-05" ixz="-3e-06" iyy="0.000361" iyz="-0.000263" izz="0.001416"/>
    </inertial>
    <visual>
      <origin rpy="0 0 0" xyz="0.099126 -0.023954 1.164815"/>
      <geometry>
        <mesh filename="file:///home/ubuntu/ethr_rc_robot_assets/humanoid-description/humanoid_final_copy_description/meshes/foot_right_1.stl" scale="0.001 0.001 0.001"/>
      </geometry>
      <material name="silver"/>
    </visual>
    <collision>
      <origin rpy="0 0 0" xyz="0.099126 -0.023954 1.164815"/>
      <geometry>
        <mesh filename="file:///home/ubuntu/ethr_rc_robot_assets/humanoid-description/humanoid_final_copy_description/meshes/foot_right_1.stl" scale="0.001 0.001 0.001"/>
      </geometry>
    </collision>
  </link>
  <link name="foot_left_1">
    <inertial>
      <origin rpy="0 0 0" xyz="-0.014477700791935832 -0.01322658635044284 -0.03966551159242693"/>
      <mass value="0.5416388803238992"/>
      <inertia ixx="0.001545" ixy="-1.6e-05" ixz="-4e-06" iyy="0.000364" iyz="-0.000269" izz="0.001413"/>
    </inertial>
    <visual>
      <origin rpy="0 0 0" xyz="-0.153489 -0.026465 1.164798"/>
      <geometry>
        <mesh filename="file:///home/ubuntu/ethr_rc_robot_assets/humanoid-description/humanoid_final_copy_description/meshes/foot_left_1.stl" scale="0.001 0.001 0.001"/>
      </geometry>
      <material name="silver"/>
    </visual>
    <collision>
      <origin rpy="0 0 0" xyz="-0.153489 -0.026465 1.164798"/>
      <geometry>
        <mesh filename="file:///home/ubuntu/ethr_rc_robot_assets/humanoid-description/humanoid_final_copy_description/meshes/foot_left_1.stl" scale="0.001 0.001 0.001"/>
      </geometry>
    </collision>
  </link>
  <link name="upper_plate_right_1">
    <inertial>
      <origin rpy="0 0 0" xyz="0.004175342132463372 0.005438315567194187 1.1018872640655708e-05"/>
      <mass value="0.0340815427988414"/>
      <inertia ixx="6e-06" ixy="-1e-06" ixz="-0.0" iyy="1.2e-05" iyz="0.0" izz="9e-06"/>
    </inertial>
    <visual>
      <origin rpy="0 0 0" xyz="-0.139246 -0.048595 0.979742"/>
      <geometry>
        <mesh filename="file:///home/ubuntu/ethr_rc_robot_assets/humanoid-description/humanoid_final_copy_description/meshes/upper_plate_right_1.stl" scale="0.001 0.001 0.001"/>
      </geometry>
      <material name="silver"/>
    </visual>
    <collision>
      <origin rpy="0 0 0" xyz="-0.139246 -0.048595 0.979742"/>
      <geometry>
        <mesh filename="file:///home/ubuntu/ethr_rc_robot_assets/humanoid-description/humanoid_final_copy_description/meshes/upper_plate_right_1.stl" scale="0.001 0.001 0.001"/>
      </geometry>
    </collision>
  </link>
  <link name="lower_plate_right_1">
    <inertial>
      <origin rpy="0 0 0" xyz="-0.004030605550805144 0.005545938638489872 7.046790873044273e-06"/>
      <mass value="0.0340815427988414"/>
      <inertia ixx="6e-06" ixy="1e-06" ixz="0.0" iyy="1.2e-05" iyz="0.0" izz="9e-06"/>
    </inertial>
    <visual>
      <origin rpy="0 0 0" xyz="-0.1394 -0.048761 1.079742"/>
      <geometry>
        <mesh filename="file:///home/ubuntu/ethr_rc_robot_assets/humanoid-description/humanoid_final_copy_description/meshes/lower_plate_right_1.stl" scale="0.001 0.001 0.001"/>
      </geometry>
      <material name="silver"/>
    </visual>
    <collision>
      <origin rpy="0 0 0" xyz="-0.1394 -0.048761 1.079742"/>
      <geometry>
        <mesh filename="file:///home/ubuntu/ethr_rc_robot_assets/humanoid-description/humanoid_final_copy_description/meshes/lower_plate_right_1.stl" scale="0.001 0.001 0.001"/>
      </geometry>
    </collision>
  </link>
  <link name="upper_plate_left_1">
    <inertial>
      <origin rpy="0 0 0" xyz="0.004166996470756162 0.005444121527016524 -2.1904718909060428e-05"/>
      <mass value="0.0340815427988414"/>
      <inertia ixx="6e-06" ixy="-1e-06" ixz="0.0" iyy="1.2e-05" iyz="-0.0" izz="9e-06"/>
    </inertial>
    <visual>
      <origin rpy="0 0 0" xyz="0.113407 -0.047193 0.979898"/>
      <geometry>
        <mesh filename="file:///home/ubuntu/ethr_rc_robot_assets/humanoid-description/humanoid_final_copy_description/meshes/upper_plate_left_1.stl" scale="0.001 0.001 0.001"/>
      </geometry>
      <material name="silver"/>
    </visual>
    <collision>
      <origin rpy="0 0 0" xyz="0.113407 -0.047193 0.979898"/>
      <geometry>
        <mesh filename="file:///home/ubuntu/ethr_rc_robot_assets/humanoid-description/humanoid_final_copy_description/meshes/upper_plate_left_1.stl" scale="0.001 0.001 0.001"/>
      </geometry>
    </collision>
  </link>
  <link name="lower_plate_left_1">
    <inertial>
      <origin rpy="0 0 0" xyz="-0.004039310160642823 0.0055401144585542975 -2.677075119006389e-05"/>
      <mass value="0.0340815427988414"/>
      <inertia ixx="6e-06" ixy="1e-06" ixz="-0.0" iyy="1.2e-05" iyz="-0.0" izz="9e-06"/>
    </inertial>
    <visual>
      <origin rpy="0 0 0" xyz="0.113251 -0.046747 1.079897"/>
      <geometry>
        <mesh filename="file:///home/ubuntu/ethr_rc_robot_assets/humanoid-description/humanoid_final_copy_description/meshes/lower_plate_left_1.stl" scale="0.001 0.001 0.001"/>
      </geometry>
      <material name="silver"/>
    </visual>
    <collision>
      <origin rpy="0 0 0" xyz="0.113251 -0.046747 1.079897"/>
      <geometry>
        <mesh filename="file:///home/ubuntu/ethr_rc_robot_assets/humanoid-description/humanoid_final_copy_description/meshes/lower_plate_left_1.stl" scale="0.001 0.001 0.001"/>
      </geometry>
    </collision>
  </link>
  <link name="rotor_neck_1">
    <inertial>
      <origin rpy="0 0 0" xyz="-7.303083084764499e-06 -7.394669032956269e-05 -0.019503268907416882"/>
      <mass value="0.570"/>
      <inertia ixx="0.000661" ixy="1e-06" ixz="-1e-06" iyy="0.000654" iyz="-2e-06" izz="0.000614"/>
    </inertial>
    <visual>
      <origin rpy="0 0 0" xyz="-0.003881 -0.059936 -0.299514"/>
      <geometry>
        <mesh filename="file:///home/ubuntu/ethr_rc_robot_assets/humanoid-description/humanoid_final_copy_description/meshes/rotor_neck_1.stl" scale="0.001 0.001 0.001"/>
      </geometry>
      <material name="silver"/>
    </visual>
    <collision>
      <origin rpy="0 0 0" xyz="-0.003881 -0.059936 -0.299514"/>
      <geometry>
        <mesh filename="file:///home/ubuntu/ethr_rc_robot_assets/humanoid-description/humanoid_final_copy_description/meshes/rotor_neck_1.stl" scale="0.001 0.001 0.001"/>
      </geometry>
    </collision>
  </link>
  <link name="neck_connector_plate_1">
    <inertial>
      <origin rpy="0 0 0" xyz="0.0029445070771169377 -0.000517806439498697 0.02413636479608705"/>
      <mass value="0.25166399201918993"/>
      <inertia ixx="0.000321" ixy="0.0" ixz="-2.2e-05" iyy="0.000375" iyz="-4e-06" izz="0.000338"/>
    </inertial>
    <visual>
      <origin rpy="0 0 0" xyz="-0.003862 -0.059996 -0.311707"/>
      <geometry>
        <mesh filename="file:///home/ubuntu/ethr_rc_robot_assets/humanoid-description/humanoid_final_copy_description/meshes/neck_connector_plate_1.stl" scale="0.001 0.001 0.001"/>
      </geometry>
      <material name="silver"/>
    </visual>
    <collision>
      <origin rpy="0 0 0" xyz="-0.003862 -0.059996 -0.311707"/>
      <geometry>
        <mesh filename="file:///home/ubuntu/ethr_rc_robot_assets/humanoid-description/humanoid_final_copy_description/meshes/neck_connector_plate_1.stl" scale="0.001 0.001 0.001"/>
      </geometry>
    </collision>
  </link>
  <link name="flexor_neck_1">
    <inertial>
      <origin rpy="0 0 0" xyz="0.019502252438317345 -0.0002644791516771827 9.894512524089016e-06"/>
      <mass value="0.570"/>
      <inertia ixx="0.000614" ixy="2e-06" ixz="-2e-06" iyy="0.000661" iyz="-1e-06" izz="0.000654"/>
    </inertial>
    <visual>
      <origin rpy="0 0 0" xyz="0.026219 -0.060608 -0.364808"/>
      <geometry>
        <mesh filename="file:///home/ubuntu/ethr_rc_robot_assets/humanoid-description/humanoid_final_copy_description/meshes/flexor_neck_1.stl" scale="0.001 0.001 0.001"/>
      </geometry>
      <material name="silver"/>
    </visual>
    <collision>
      <origin rpy="0 0 0" xyz="0.026219 -0.060608 -0.364808"/>
      <geometry>
        <mesh filename="file:///home/ubuntu/ethr_rc_robot_assets/humanoid-description/humanoid_final_copy_description/meshes/flexor_neck_1.stl" scale="0.001 0.001 0.001"/>
      </geometry>
    </collision>
  </link>
  <link name="head_1">
    <inertial>
      <origin rpy="0 0 0" xyz="0.042158556227868994 -0.06193240817472676 0.12202699675420742"/>
      <mass value="1.5"/>
      <inertia ixx="0.069203" ixy="5.1e-05" ixz="-0.000152" iyy="0.068434" iyz="-0.005284" izz="0.062772"/>
    </inertial>
    <visual>
      <origin rpy="0 0 0" xyz="0.038411 -0.06075 -0.364789"/>
      <geometry>
        <mesh filename="file:///home/ubuntu/ethr_rc_robot_assets/humanoid-description/humanoid_final_copy_description/meshes/head_1.stl" scale="0.001 0.001 0.001"/>
      </geometry>
      <material name="silver"/>
    </visual>
    <collision>
      <origin rpy="0 0 0" xyz="0.038411 -0.06075 -0.364789"/>
      <geometry>
        <mesh filename="file:///home/ubuntu/ethr_rc_robot_assets/humanoid-description/humanoid_final_copy_description/meshes/head_1.stl" scale="0.001 0.001 0.001"/>
      </geometry>
    </collision>
  </link>
  <joint name="left_shoulder_flexor" type="revolute">
    <origin rpy="0 0 0" xyz="0.016992 -0.039682 0.003934"/>
    <parent link="motor_1_left_1"/>
    <child link="shoulder_upper_left_1"/>
    <axis xyz="0.977757 -0.010376 0.209482"/>
    <limit effort="100" lower="-2.094395" upper="2.094395" velocity="100"/>
  </joint>
  <joint name="left_arm_link0" type="fixed">
    <origin rpy="0 0 0" xyz="-0.259851 0.045254 0.204406"/>
    <parent link="shoulder_upper_left_1"/>
    <child link="motor_2_left_1"/>
  </joint>
  <joint name="left_shoulder_abductor" type="revolute">
    <origin rpy="0 0 0" xyz="0.303473 -0.084124 -0.172234"/>
    <parent link="motor_2_left_1"/>
    <child link="shoulder_lower_left_1"/>
    <axis xyz="-0.114809 -0.86233 0.493159"/>
    <limit effort="100" lower="-0.261799" upper="3.141593" velocity="100"/>
  </joint>
  <joint name="left_arm_rotor0" type="revolute">
    <origin rpy="0 0 0" xyz="0.012819 0.007176 -0.059478"/>
    <parent link="shoulder_lower_left_1"/>
    <child link="motor_3_left_1"/>
    <axis xyz="0.175526 -0.506241 -0.844341"/>
    <limit effort="100" lower="-1.570796" upper="1.570796" velocity="100"/>
  </joint>
  <joint name="left_arm_link1" type="fixed">
    <origin rpy="0 0 0" xyz="-0.002045 -0.005982 -0.06713"/>
    <parent link="motor_3_left_1"/>
    <child link="elbow_upper_left_1"/>
  </joint>
  <joint name="left_arm_link2" type="fixed">
    <origin rpy="0 0 0" xyz="0.005662 -0.050822 -0.087548"/>
    <parent link="elbow_upper_left_1"/>
    <child link="motor_4_left_1"/>
  </joint>
  <joint name="left_elbow_flexor" type="revolute">
    <origin rpy="0 0 0" xyz="0.057656 -0.032614 0.01259"/>
    <parent link="motor_4_left_1"/>
    <child link="elbow_lower_left_1"/>
    <axis xyz="0.977757 -0.010376 0.209482"/>
    <limit effort="100" lower="-1.832596" upper="1.832596" velocity="100"/>
  </joint>
  <joint name="left_arm_link3" type="fixed">
    <origin rpy="0 0 0" xyz="-0.027872 -0.051919 -0.031985"/>
    <parent link="elbow_lower_left_1"/>
    <child link="motor_5_left_1"/>
  </joint>
  <joint name="left_arm_rotor1" type="revolute">
    <origin rpy="0 0 0" xyz="0.014091 -0.002451 -0.065892"/>
    <parent link="motor_5_left_1"/>
    <child link="wrist_upper_left_1"/>
    <axis xyz="0.175526 -0.506241 -0.844341"/>
    <limit effort="100" lower="-1.570796" upper="1.570796" velocity="100"/>
  </joint>
  <joint name="left_arm_link4" type="fixed">
    <origin rpy="0 0 0" xyz="-0.019467 0.007511 -0.041058"/>
    <parent link="wrist_upper_left_1"/>
    <child link="motor_6_left_1"/>
  </joint>
  <joint name="left_wrist_abductor" type="revolute">
    <origin rpy="0 0 0" xyz="0.023091 -0.059567 0.021565"/>
    <parent link="motor_6_left_1"/>
    <child link="wrist_lower_left_1"/>
    <axis xyz="-0.114809 -0.86233 0.493159"/>
    <limit effort="100" lower="-1.570796" upper="1.570796" velocity="100"/>
  </joint>
  <joint name="left_arm_link5" type="fixed">
    <origin rpy="0 0 0" xyz="0.031163 0.008759 -0.048286"/>
    <parent link="wrist_lower_left_1"/>
    <child link="motor_7_left_1"/>
  </joint>
  <joint name="left_wrist_flexor" type="revolute">
    <origin rpy="0 0 0" xyz="0.018474 -0.016336 -0.024264"/>
    <parent link="motor_7_left_1"/>
    <child link="eef_left_1"/>
    <axis xyz="0.977757 -0.010376 0.209482"/>
    <limit effort="100" lower="-1.570796" upper="1.570796" velocity="100"/>
  </joint>
  <joint name="right_shoulder_flexor" type="revolute">
    <origin rpy="0 0 0" xyz="-0.017925 -0.039275 0.003877"/>
    <parent link="motor_1_right_1"/>
    <child link="shoulder_upper_right_1"/>
    <axis xyz="0.978402 -0.012429 -0.206336"/>
    <limit effort="100" lower="-2.094395" upper="2.094395" velocity="100"/>
  </joint>
  <joint name="right_arm_link0" type="fixed">
    <origin rpy="0 0 0" xyz="-0.235961 -0.179058 -0.0995"/>
    <parent link="shoulder_upper_right_1"/>
    <child link="motor_2_right_1"/>
  </joint>
  <joint name="right_shoulder_abductor" type="revolute">
    <origin rpy="0 0 0" xyz="0.191341 0.141216 0.13153"/>
    <parent link="motor_2_right_1"/>
    <child link="shoulder_lower_right_1"/>
    <axis xyz="-0.093088 0.864754 -0.493494"/>
    <limit effort="100" lower="-0.261799" upper="3.141593" velocity="100"/>
  </joint>
  <joint name="right_arm_rotor0" type="revolute">
    <origin rpy="0 0 0" xyz="-0.012456 0.007471 -0.059518"/>
    <parent link="shoulder_lower_right_1"/>
    <child link="motor_3_right_1"/>
    <axis xyz="0.184563 0.502043 0.84492"/>
    <limit effort="100" lower="-1.570796" upper="1.570796" velocity="100"/>
  </joint>
  <joint name="right_arm_link1" type="fixed">
    <origin rpy="0 0 0" xyz="-0.024029 -0.053562 -0.033169"/>
    <parent link="motor_3_right_1"/>
    <child link="elbow_upper_right_1"/>
  </joint>
  <joint name="right_arm_link2" type="fixed">
    <origin rpy="0 0 0" xyz="0.025119 -0.01908 -0.094328"/>
    <parent link="elbow_upper_right_1"/>
    <child link="motor_4_right_1"/>
  </joint>
  <joint name="right_elbow_flexor" type="revolute">
    <origin rpy="0 0 0" xyz="-0.063974 -0.015328 -0.014792"/>
    <parent link="motor_4_right_1"/>
    <child link="elbow_lower_right_1"/>
    <axis xyz="0.978402 -0.012429 -0.206336"/>
    <limit effort="100" lower="-1.832596" upper="1.832596" velocity="100"/>
  </joint>
  <joint name="right_arm_link3" type="fixed">
    <origin rpy="0 0 0" xyz="0.052382 -0.039065 -0.04551"/>
    <parent link="elbow_lower_right_1"/>
    <child link="motor_5_right_1"/>
  </joint>
  <joint name="right_arm_rotor1" type="revolute">
    <origin rpy="0 0 0" xyz="-0.039558 -0.015616 -0.052324"/>
    <parent link="motor_5_right_1"/>
    <child link="wrist_upper_right_1"/>
    <axis xyz="0.184563 0.502043 0.84492"/>
    <limit effort="100" lower="-1.570796" upper="1.570796" velocity="100"/>
  </joint>
  <joint name="right_arm_link4" type="fixed">
    <origin rpy="0 0 0" xyz="-0.004392 0.015431 -0.021757"/>
    <parent link="wrist_upper_right_1"/>
    <child link="motor_6_right_1"/>
  </joint>
  <joint name="right_wrist_abductor" type="revolute">
    <origin rpy="0 0 0" xyz="-0.000381 -0.067388 0.002251"/>
    <parent link="motor_6_right_1"/>
    <child link="wrist_lower_right_1"/>
    <axis xyz="-0.093088 0.864754 -0.493494"/>
    <limit effort="100" lower="-1.570796" upper="1.570796" velocity="100"/>
  </joint>
  <joint name="right_arm_link5" type="fixed">
    <origin rpy="0 0 0" xyz="0.008874 0.024839 -0.085113"/>
    <parent link="wrist_lower_right_1"/>
    <child link="motor_7_right_1"/>
  </joint>
  <joint name="right_wrist_flexor" type="revolute">
    <origin rpy="0 0 0" xyz="-0.058441 -0.03126 0.012403"/>
    <parent link="motor_7_right_1"/>
    <child link="eef_right_1"/>
    <axis xyz="0.978402 -0.012429 -0.206336"/>
    <limit effort="100" lower="-1.570796" upper="1.570796" velocity="100"/>
  </joint>
  <joint name="right_torso_arm_link" type="fixed">
    <origin rpy="0 0 0" xyz="-0.173947 0.09865 0.225664"/>
    <parent link="base_link"/>
    <child link="motor_1_right_1"/>
  </joint>
  <joint name="left_torso_arm_link" type="fixed">
    <origin rpy="0 0 0" xyz="0.182799 0.094491 0.226237"/>
    <parent link="base_link"/>
    <child link="motor_1_left_1"/>
  </joint>
  <joint name="hip_rotor" type="revolute">
    <origin rpy="0 0 0" xyz="0.004471 0.043019 -0.190181"/>
    <parent link="base_link"/>
    <child link="rotor_waist_1"/>
    <axis xyz="-0.001551 0.004936 0.999987"/>
    <limit effort="100" lower="-0.174533" upper="0.523599" velocity="100"/>
  </joint>
  <joint name="hip_link0" type="fixed">
    <origin rpy="0 0 0" xyz="1.6e-05 -4.9e-05 -0.01005"/>
    <parent link="rotor_waist_1"/>
    <child link="Middle_Connector_Platre_1"/>
  </joint>
  <joint name="hip_abductor0" type="revolute">
    <origin rpy="0 0 0" xyz="0.000802 0.064798 -0.008329"/>
    <parent link="Middle_Connector_Platre_1"/>
    <child link="abductor_central_1"/>
    <axis xyz="-0.011665 -0.99992 0.004918"/>
    <limit effort="100" lower="-0.174533" upper="0.174533" velocity="100"/>
  </joint>
  <joint name="hip_link1" type="fixed">
    <origin rpy="0 0 0" xyz="0.000275 0.023548 -0.000116"/>
    <parent link="abductor_central_1"/>
    <child link="hip_subframe_1"/>
  </joint>
  <joint name="hip_link2" type="fixed">
    <origin rpy="0 0 0" xyz="0.151557 -0.136301 -0.363524"/>
    <parent link="hip_subframe_1"/>
    <child link="flexor_right_1"/>
  </joint>
  <joint name="hip_link3" type="fixed">
    <origin rpy="0 0 0" xyz="-0.162337 -0.128978 -0.363533"/>
    <parent link="hip_subframe_1"/>
    <child link="flexor_left_1"/>
  </joint>
  <joint name="left_leg_flexor" type="revolute">
    <origin rpy="0 0 0" xyz="0.342382 0.017455 0.272632"/>
    <parent link="flexor_left_1"/>
    <child link="flexor_plate_left_1"/>
    <axis xyz="-0.966276 0.012537 0.257204"/>
    <limit effort="100" lower="-1.570796" upper="1.570796" velocity="100"/>
  </joint>
  <joint name="right_leg_flexor" type="revolute">
    <origin rpy="0 0 0" xyz="-0.333853 0.029003 0.272029"/>
    <parent link="flexor_right_1"/>
    <child link="flexor_plate_right_1"/>
    <axis xyz="-0.965458 0.009982 -0.260369"/>
    <limit effort="100" lower="-1.570796" upper="1.570796" velocity="100"/>
  </joint>
  <joint name="right_leg_abductor" type="revolute">
    <origin rpy="0 0 0" xyz="0.05605 0.08772 -0.015155"/>
    <parent link="flexor_plate_right_1"/>
    <child link="abductor_right_1"/>
    <axis xyz="-0.013787 -0.962337 0.271509"/>
    <limit effort="100" lower="-1.570796" upper="0.174533" velocity="100"/>
  </joint>
  <joint name="left_leg_abductor" type="revolute">
    <origin rpy="0 0 0" xyz="-0.053903 0.089306 -0.015212"/>
    <parent link="flexor_plate_left_1"/>
    <child link="abductor_left_1"/>
    <axis xyz="0.01113 0.964012 -0.265627"/>
    <limit effort="100" lower="-1.570796" upper="0.174533" velocity="100"/>
  </joint>
  <joint name="hip_link4" type="fixed">
    <origin rpy="0 0 0" xyz="-0.258947 -0.2151 -0.286068"/>
    <parent link="abductor_left_1"/>
    <child link="femural_head_left_1"/>
  </joint>
  <joint name="hip_link5" type="fixed">
    <origin rpy="0 0 0" xyz="0.242956 -0.225689 -0.284452"/>
    <parent link="abductor_right_1"/>
    <child link="femural_head_right_1"/>
  </joint>
  <joint name="hip_link6" type="fixed">
    <origin rpy="0 0 0" xyz="0.004377 0.10867 -0.150504"/>
    <parent link="femural_head_right_1"/>
    <child link="rotor_right_1"/>
  </joint>
  <joint name="hip_link7" type="fixed">
    <origin rpy="0 0 0" xyz="0.004318 0.108675 -0.150499"/>
    <parent link="femural_head_left_1"/>
    <child link="rotor_left_1"/>
  </joint>
  <joint name="left_leg_rotor" type="revolute">
    <origin rpy="0 0 0" xyz="0.25234 0.019737 0.25612"/>
    <parent link="rotor_left_1"/>
    <child link="femur_left_1"/>
    <axis xyz="0.00154 0.001655 -0.999997"/>
    <limit effort="100" lower="-1.570796" upper="1.570796" velocity="100"/>
  </joint>
  <joint name="right_leg_rotor" type="revolute">
    <origin rpy="0 0 0" xyz="-0.249858 0.029237 0.255041"/>
    <parent link="rotor_right_1"/>
    <child link="femur_right_1"/>
    <axis xyz="-0.001558 0.004457 0.999989"/>
    <limit effort="100" lower="-1.570796" upper="1.570796" velocity="100"/>
  </joint>
  <joint name="right_leg_link0" type="fixed">
    <origin rpy="0 0 0" xyz="0.034026 -0.002006 -0.362477"/>
    <parent link="femur_right_1"/>
    <child link="knee_right_1"/>
  </joint>
  <joint name="left_leg_link0" type="fixed">
    <origin rpy="0 0 0" xyz="0.034018 0.000159 -0.362484"/>
    <parent link="femur_left_1"/>
    <child link="knee_left_1"/>
  </joint>
  <joint name="right_leg_link2" type="fixed">
    <origin rpy="0 0 0" xyz="-0.047145 0.022565 -0.222205"/>
    <parent link="tibia_subframe_right_1"/>
    <child link="ankle_actuator_upper_right_1"/>
  </joint>
  <joint name="right_leg_link1" type="fixed">
    <origin rpy="0 0 0" xyz="-0.0473 0.023011 -0.122206"/>
    <parent link="tibia_subframe_right_1"/>
    <child link="ankle_actuator_lower_right_1"/>
  </joint>
  <joint name="left_leg_link1" type="fixed">
    <origin rpy="0 0 0" xyz="-0.047267 0.023829 -0.122061"/>
    <parent link="tibia_subframe_left_1"/>
    <child link="ankle_actuator_upper_left_1"/>
  </joint>
  <joint name="left_leg_link2" type="fixed">
    <origin rpy="0 0 0" xyz="-0.047113 0.023995 -0.222061"/>
    <parent link="tibia_subframe_left_1"/>
    <child link="ankle_actuator_lower_left_1"/>
  </joint>
  <joint name="left_knee" type="revolute">
    <origin rpy="0 0 0" xyz="0.023045 -0.000304 3.5e-05"/>
    <parent link="knee_left_1"/>
    <child link="tibia_subframe_left_1"/>
    <axis xyz="0.999912 -0.013179 0.001518"/>
    <limit effort="100" lower="-1.570796" upper="1.570796" velocity="100"/>
  </joint>
  <joint name="right_knee" type="revolute">
    <origin rpy="0 0 0" xyz="0.023045 -0.000268 3.7e-05"/>
    <parent link="knee_right_1"/>
    <child link="tibia_subframe_right_1"/>
    <axis xyz="0.999931 -0.011657 0.001609"/>
    <limit effort="100" lower="-1.570796" upper="1.570796" velocity="100"/>
  </joint>
  <joint name="left_ankle_roll" type="revolute">
    <origin rpy="0 0 0" xyz="-0.047427 -0.009862 -0.307118"/>
    <parent link="tibia_subframe_left_1"/>
    <child link="ankle_spherical_joint_left_1"/>
    <axis xyz="-0.013176 -0.999912 -0.001675"/>
    <limit effort="100" lower="-0.349066" upper="0.349066" velocity="100"/>
  </joint>
  <joint name="right_ankle_roll" type="revolute">
    <origin rpy="0 0 0" xyz="-0.047073 0.016687 -0.307179"/>
    <parent link="tibia_subframe_right_1"/>
    <child link="ankle_spherical_joint_right_1"/>
    <axis xyz="0.011664 0.999922 -0.004439"/>
    <limit effort="100" lower="-0.349066" upper="0.349066" velocity="100"/>
  </joint>
  <joint name="right_ankle_pitch" type="revolute">
    <origin rpy="0 0 0" xyz="0.014083 -0.014415 4.5e-05"/>
    <parent link="ankle_spherical_joint_right_1"/>
    <child link="foot_right_1"/>
    <axis xyz="0.999931 -0.01167 -0.001231"/>
    <limit effort="100" lower="-1.22173" upper="0.087266" velocity="100"/>
  </joint>
  <joint name="left_ankle_pitch" type="revolute">
    <origin rpy="0 0 0" xyz="0.014436 0.014061 5e-06"/>
    <parent link="ankle_spherical_joint_left_1"/>
    <child link="foot_left_1"/>
    <axis xyz="0.999912 -0.013174 -0.001328"/>
    <limit effort="100" lower="-1.22173" upper="0.087266" velocity="100"/>
  </joint>
  <joint name="left_leg_robstride_upper" type="revolute">
    <origin rpy="0 0 0" xyz="3.3e-05 0.0025 4e-06"/>
    <parent link="ankle_actuator_upper_left_1"/>
    <child link="upper_plate_right_1"/>
    <axis xyz="-0.013176 -0.999912 -0.001675"/>
    <limit effort="100" lower="0.0" upper="6.283185" velocity="100"/>
  </joint>
  <joint name="left_leg_robstride_lower" type="revolute">
    <origin rpy="0 0 0" xyz="3.3e-05 0.0025 4e-06"/>
    <parent link="ankle_actuator_lower_left_1"/>
    <child link="lower_plate_right_1"/>
    <axis xyz="-0.013176 -0.999912 -0.001675"/>
    <limit effort="100" lower="0.0" upper="6.283185" velocity="100"/>
  </joint>
  <joint name="right_leg_robstride_upper" type="revolute">
    <origin rpy="0 0 0" xyz="2.9e-05 0.0025 -1.1e-05"/>
    <parent link="ankle_actuator_lower_right_1"/>
    <child link="upper_plate_left_1"/>
    <axis xyz="-0.011664 -0.999922 0.004439"/>
    <limit effort="100" lower="0.0" upper="6.283185" velocity="100"/>
  </joint>
  <joint name="right_leg_robstride_lower" type="revolute">
    <origin rpy="0 0 0" xyz="3e-05 0.0025 -1.1e-05"/>
    <parent link="ankle_actuator_upper_right_1"/>
    <child link="lower_plate_left_1"/>
    <axis xyz="-0.011664 -0.999922 0.004439"/>
    <limit effort="100" lower="0.0" upper="6.283185" velocity="100"/>
  </joint>
  <joint name="torso_neck_link" type="fixed">
    <origin rpy="0 0 0" xyz="0.003881 0.059936 0.299514"/>
    <parent link="base_link"/>
    <child link="rotor_neck_1"/>
  </joint>
  <joint name="neck_rotor" type="revolute">
    <origin rpy="0 0 0" xyz="-1.9e-05 6e-05 0.012193"/>
    <parent link="rotor_neck_1"/>
    <child link="neck_connector_plate_1"/>
    <axis xyz="-0.001551 0.004936 0.999987"/>
    <limit effort="100" lower="0.0" upper="6.283185" velocity="100"/>
  </joint>
  <joint name="Rigid 140" type="fixed">
    <origin rpy="0 0 0" xyz="-0.030081 0.000612 0.053101"/>
    <parent link="neck_connector_plate_1"/>
    <child link="flexor_neck_1"/>
  </joint>
  <joint name="neck_flexor" type="revolute">
    <origin rpy="0 0 0" xyz="-0.012192 0.000142 -1.9e-05"/>
    <parent link="flexor_neck_1"/>
    <child link="head_1"/>
    <axis xyz="-0.999931 0.011657 -0.001608"/>
    <limit effort="100" lower="-0.436332" upper="1.570796" velocity="100"/>
  </joint>
</robot>
